File: XRD_source_data/Hematite.ras
*RAS_DATA_START
*RAS_HEADER_START
*DISP_FMT_X "%.2f"
*DISP_FMT_Y "%.0f"
*DISP_FULLSCALE "699.6000000000"
*DISP_LINE_COLOR "255.0000000000"
*DISP_LINE_STYLE "0.0000000000"
*DISP_LINE_WIDTH "0.2500000000"
*DISP_NOTE "Collected Data-1"
*DISP_OFFSET_Y "0.0000000000"
*DISP_PEAKSEARCH_UNIT_Y "COUNTS"
*DISP_RANGE_BOTTOM "0.0000000000"
*DISP_RANGE_LEFT "10.0000000000"
*DISP_RANGE_LOGCUTOFF "0.0100000000"
*DISP_RANGE_RIGHT "90.0000000000"
*DISP_RANGE_TOP "699.6000000000"
*DISP_SCALE_MODE_Y "0.0000000000"
*DISP_TAB_NAME "Theta/2-Theta"
*DISP_TITLE_Y "Intensity"
*DISP_UNIT_Y "COUNTS"
*DISP_WINDOW_NAME "MSG_MACROENGINE"
*FILE_COMMENT " "
*FILE_MD5 ""
*FILE_MEMO " "
*FILE_OPERATOR "Administrator"
*FILE_PART_ID "MEAS_PBEA_00223"
*FILE_SAMPLE "Hematite"
*FILE_TYPE "RAS_RAW"
*FILE_USERGROUP "System Manager"
*FILE_VERSION "1.0000000000"
*HW_ATTACHMENT_ID "ATT1031"
*HW_ATTACHMENT_NAME "6サンプルチェンジャ|ASC-6"
*HW_COUNTER_ID-0 "CUT0021"
*HW_COUNTER_ID-1 "CUT0020"
*HW_COUNTER_ID-2 "CUT0020"
*HW_COUNTER_ID-3 "CMC0021"
*HW_COUNTER_NAME-0 "SC-70|SC-70"
*HW_COUNTER_NAME-1 "None|None"
*HW_COUNTER_NAME-2 "None|None"
*HW_COUNTER_NAME-3 "検出器モノクロメータ|Detector monochromator"
*HW_COUNTER_SELECT_NAME "SC-70|SC-70"
*HW_ECP_HV "714.0000000000"
*HW_ECP_HV_UNIT "V"
*HW_GONIOMETER_ID "GON0070"
*HW_GONIOMETER_NAME "MiniFlex 300/600|MiniFlex 300/600"
*HW_GONIOMETER_RADIUS-0 "79.0"
*HW_GONIOMETER_RADIUS-1 "91.5"
*HW_GONIOMETER_RADIUS-2 "150.0"
*HW_GONIOMETER_RADIUS-3 "0"
*HW_GONIOMETER_RADIUS-4 "103.4"
*HW_GONIOMETER_RADIUS-5 "150.0"
*HW_GONIOMETER_RADIUS-6 "46.6"
*HW_GONIOMETER_RADIUS-7 "160.0"
*HW_I_OPT_ID-0 "ISL0021"
*HW_I_OPT_ID-1 "ISO0021"
*HW_I_OPT_NAME-0 "発散スリット|Divergence slit"
*HW_I_OPT_NAME-1 "入射平行スリット|Incident parallel slit"
*HW_R_ATTENUATER_AUTOMODE "0"
*HW_R_OPT_ID-0 "RSS0021"
*HW_R_OPT_ID-1 "RSO0021"
*HW_R_OPT_ID-2 "RRS0021"
*HW_R_OPT_NAME-0 "散乱スリット|Scattering slit"
*HW_R_OPT_NAME-1 "受光平行スリット|Receiving soller slit"
*HW_R_OPT_NAME-2 "受光スリット|Receiving slit"
*HW_SAMPLE_HOLDER_ID "SMP0000"
*HW_SAMPLE_HOLDER_NAME "無し|None"
*HW_XG_CURRENT_MAX "50"
*HW_XG_CURRENT_MIN "2"
*HW_XG_CURRENT_RESOLUTION "2"
*HW_XG_CURRENT_UNIT "mA"
*HW_XG_FOCUS "1mm x 10mm"
*HW_XG_FOCUS_TYPE "Normal"
*HW_XG_ID "1062"
*HW_XG_NAME "300W/600W 封入管-A|300W/600W Sealed tube-A"
*HW_XG_TARGET_ATOMIC_NUMBER "29.0000000000"
*HW_XG_TARGET_NAME "Cu"
*HW_XG_TYPE "Compact"
*HW_XG_VOLTAGE_MAX "60"
*HW_XG_VOLTAGE_MIN "20"
*HW_XG_VOLTAGE_RESOLUTION "2"
*HW_XG_VOLTAGE_UNIT "kV"
*HW_XG_WATT_MAX "2.000"
*HW_XG_WATT_UNIT "kW"
*HW_XG_WAVE_LENGTH_ALPHA1 "1.540593"
*HW_XG_WAVE_LENGTH_ALPHA2 "1.544414"
*HW_XG_WAVE_LENGTH_BETA "1.392250"
*MEAS_COND_AXIS_NAME-0 "Theta/2-Theta"
*MEAS_COND_AXIS_NAME-1 "Spin"
*MEAS_COND_AXIS_NAME-2 "Change"
*MEAS_COND_AXIS_NAME-3 "Soller(inc.)"
*MEAS_COND_AXIS_NAME-4 "IHS"
*MEAS_COND_AXIS_NAME-5 "DS"
*MEAS_COND_AXIS_NAME-6 "SS"
*MEAS_COND_AXIS_NAME-7 "Soller(rec.)"
*MEAS_COND_AXIS_NAME-8 "RS"
*MEAS_COND_AXIS_NAME-9 "Filter"
*MEAS_COND_AXIS_NAME-10 "Monochromator"
*MEAS_COND_AXIS_NAME-11 "HV"
*MEAS_COND_AXIS_NAME-12 "PHA"
*MEAS_COND_AXIS_NAME_INTERNAL-0 "TwoThetaTheta"
*MEAS_COND_AXIS_NAME_INTERNAL-1 "Spin"
*MEAS_COND_AXIS_NAME_INTERNAL-2 "Change"
*MEAS_COND_AXIS_NAME_INTERNAL-3 "IncidentSollerSlit"
*MEAS_COND_AXIS_NAME_INTERNAL-4 "IncidentAxdSlit"
*MEAS_COND_AXIS_NAME_INTERNAL-5 "IncidentSlitBox"
*MEAS_COND_AXIS_NAME_INTERNAL-6 "ReceivingSlitBox1"
*MEAS_COND_AXIS_NAME_INTERNAL-7 "ReceivingSollerSlit"
*MEAS_COND_AXIS_NAME_INTERNAL-8 "ReceivingSlitBox2"
*MEAS_COND_AXIS_NAME_INTERNAL-9 "Filter"
*MEAS_COND_AXIS_NAME_INTERNAL-10 "CounterMonochromator"
*MEAS_COND_AXIS_NAME_INTERNAL-11 "HV"
*MEAS_COND_AXIS_NAME_INTERNAL-12 "PHA"
*MEAS_COND_AXIS_NAME_MAGICNO-0 "268632064.0000000000"
*MEAS_COND_AXIS_NAME_MAGICNO-1 "16842752.0000000000"
*MEAS_COND_AXIS_NAME_MAGICNO-2 "16842752.0000000000"
*MEAS_COND_AXIS_NAME_MAGICNO-3 "20971521.0000000000"
*MEAS_COND_AXIS_NAME_MAGICNO-4 "22020097.0000000000"
*MEAS_COND_AXIS_NAME_MAGICNO-5 "22020097.0000000000"
*MEAS_COND_AXIS_NAME_MAGICNO-6 "23068673.0000000000"
*MEAS_COND_AXIS_NAME_MAGICNO-7 "20971521.0000000000"
*MEAS_COND_AXIS_NAME_MAGICNO-8 "23068673.0000000000"
*MEAS_COND_AXIS_NAME_MAGICNO-9 "20971521.0000000000"
*MEAS_COND_AXIS_NAME_MAGICNO-10 "20971521.0000000000"
*MEAS_COND_AXIS_NAME_MAGICNO-11 "0.0000000000"
*MEAS_COND_AXIS_NAME_MAGICNO-12 "0.0000000000"
*MEAS_COND_AXIS_OFFSET-0 "0.0000000000"
*MEAS_COND_AXIS_OFFSET-1 "-"
*MEAS_COND_AXIS_OFFSET-2 "-"
*MEAS_COND_AXIS_OFFSET-3 "-"
*MEAS_COND_AXIS_OFFSET-4 "-"
*MEAS_COND_AXIS_OFFSET-5 "-"
*MEAS_COND_AXIS_OFFSET-6 "-"
*MEAS_COND_AXIS_OFFSET-7 "-"
*MEAS_COND_AXIS_OFFSET-8 "-"
*MEAS_COND_AXIS_OFFSET-9 "-"
*MEAS_COND_AXIS_OFFSET-10 "-"
*MEAS_COND_AXIS_OFFSET-11 "-"
*MEAS_COND_AXIS_OFFSET-12 "-"
*MEAS_COND_AXIS_POSITION-0 "10.0000000000"
*MEAS_COND_AXIS_POSITION-1 "0.0000000000"
*MEAS_COND_AXIS_POSITION-2 "3.0000000000"
*MEAS_COND_AXIS_POSITION-3 "2.5deg"
*MEAS_COND_AXIS_POSITION-4 "10.0mm"
*MEAS_COND_AXIS_POSITION-5 "1.250deg"
*MEAS_COND_AXIS_POSITION-6 "13.0mm(Open)"
*MEAS_COND_AXIS_POSITION-7 "5.0deg"
*MEAS_COND_AXIS_POSITION-8 "13.0mm"
*MEAS_COND_AXIS_POSITION-9 "None"
*MEAS_COND_AXIS_POSITION-10 "None"
*MEAS_COND_AXIS_POSITION-11 "714.0000000000"
*MEAS_COND_AXIS_POSITION-12 "568.7500000000"
*MEAS_COND_AXIS_UNIT-0 "deg"
*MEAS_COND_AXIS_UNIT-1 ""
*MEAS_COND_AXIS_UNIT-2 ""
*MEAS_COND_AXIS_UNIT-3 ""
*MEAS_COND_AXIS_UNIT-4 ""
*MEAS_COND_AXIS_UNIT-5 ""
*MEAS_COND_AXIS_UNIT-6 ""
*MEAS_COND_AXIS_UNIT-7 ""
*MEAS_COND_AXIS_UNIT-8 ""
*MEAS_COND_AXIS_UNIT-9 ""
*MEAS_COND_AXIS_UNIT-10 ""
*MEAS_COND_AXIS_UNIT-11 "V"
*MEAS_COND_AXIS_UNIT-12 "mV"
*MEAS_COND_CORRECTION_SLIT_COUNTERMONO "None"
*MEAS_COND_CORRECTION_SLIT_DS "1.250deg"
*MEAS_COND_CORRECTION_SLIT_FILTER "None"
*MEAS_COND_CORRECTION_SLIT_IHS "10.0mm"
*MEAS_COND_CORRECTION_SLIT_RS "13.0mm"
*MEAS_COND_CORRECTION_SLIT_SOLLER_INC "2.5deg"
*MEAS_COND_CORRECTION_SLIT_SOLLER_REC "5.0deg"
*MEAS_COND_CORRECTION_SLIT_SS "13.0mm"
*MEAS_COND_COUNTER_CNTLOSS_CORR "0.0000000000"
*MEAS_COND_COUNTER_PHABASE "568.7500000000"
*MEAS_COND_COUNTER_PHAWINDOW "926.2500000000"
*MEAS_COND_COUNTER_PHA_UNIT "mV"
*MEAS_COND_COUNTER_TAUDIFF "0.2500000000"
*MEAS_COND_COUNTER_TAUINT "0.7500000000"
*MEAS_COND_IRRADIATION_MODE "OFF"
*MEAS_COND_IRRADIATION_WIDTH ""
*MEAS_COND_OPT_ATTR " "
*MEAS_COND_OPT_NAME ""
*MEAS_COND_UNSYMMETRIC_MODE "OFF"
*MEAS_COND_XG_CURRENT "15.0000000000"
*MEAS_COND_XG_VOLTAGE "40.0000000000"
*MEAS_COND_XG_WAVE_TYPE "Ka"
*MEAS_DATA_COUNT "4001.0000000000"
*MEAS_SCAN_AXIS_X "Theta/2-Theta"
*MEAS_SCAN_AXIS_X_INTERNAL "TwoThetaTheta"
*MEAS_SCAN_END_TIME "03/07/24 14:38:08"
*MEAS_SCAN_MODE "CONTINUOUS"
*MEAS_SCAN_MONITOR "0"
*MEAS_SCAN_RESOLUTION_X "0.0025"
*MEAS_SCAN_SPEED "2.0000"
*MEAS_SCAN_SPEED_UNIT "deg/min"
*MEAS_SCAN_SPEED_USER "2.0000"
*MEAS_SCAN_START "10.0000000000"
*MEAS_SCAN_START_TIME "03/07/24 13:58:00"
*MEAS_SCAN_STEP "0.0200000000"
*MEAS_SCAN_STOP "90.0000000000"
*MEAS_SCAN_UNIT_X "deg"
*MEAS_SCAN_UNIT_Y "counts"
*SLIT_SYSTEM "0"
*RAS_HEADER_END
*RAS_INT_START
10.0000 501.0000 1.0000
10.0600 453.0000 1.0000
10.1200 441.0000 1.0000
10.1800 507.0000 1.0000
10.2400 464.0000 1.0000
10.3000 472.0000 1.0000
10.3600 460.0000 1.0000
10.4200 470.0000 1.0000
10.4800 439.0000 1.0000
10.5400 438.0000 1.0000
10.6000 460.0000 1.0000
10.6600 452.0000 1.0000
10.7200 495.0000 1.0000
10.7800 475.0000 1.0000
10.8400 490.0000 1.0000
10.9000 413.0000 1.0000
10.9600 432.0000 1.0000
11.0200 480.0000 1.0000
11.0800 424.0000 1.0000
11.1400 438.0000 1.0000
11.2000 434.0000 1.0000
11.2600 432.0000 1.0000
11.3200 453.0000 1.0000
11.3800 407.0000 1.0000
11.4400 402.0000 1.0000
11.5000 454.0000 1.0000
11.5600 409.0000 1.0000
11.6200 425.0000 1.0000
11.6800 443.0000 1.0000
11.7400 419.0000 1.0000
11.8000 409.0000 1.0000
11.8600 432.0000 1.0000
11.9200 408.0000 1.0000
11.9800 425.0000 1.0000
12.0400 398.0000 1.0000
12.1000 348.0000 1.0000
12.1600 392.0000 1.0000
12.2200 461.0000 1.0000
12.2800 433.0000 1.0000
12.3400 412.0000 1.0000
12.4000 465.0000 1.0000
12.4600 447.0000 1.0000
12.5200 430.0000 1.0000
12.5800 422.0000 1.0000
12.6400 376.0000 1.0000
12.7000 358.0000 1.0000
12.7600 405.0000 1.0000
12.8200 433.0000 1.0000
12.8800 420.0000 1.0000
12.9400 360.0000 1.0000
13.0000 361.0000 1.0000
13.0600 390.0000 1.0000
13.1200 369.0000 1.0000
13.1800 403.0000 1.0000
13.2400 413.0000 1.0000
13.3000 363.0000 1.0000
13.3600 366.0000 1.0000
13.4200 382.0000 1.0000
13.4800 366.0000 1.0000
13.5400 368.0000 1.0000
13.6000 352.0000 1.0000
13.6600 333.0000 1.0000
13.7200 386.0000 1.0000
13.7800 371.0000 1.0000
13.8400 369.0000 1.0000
13.9000 365.0000 1.0000
13.9600 365.0000 1.0000
14.0200 379.0000 1.0000
14.0800 340.0000 1.0000
14.1400 344.0000 1.0000
14.2000 370.0000 1.0000
14.2600 369.0000 1.0000
14.3200 301.0000 1.0000
14.3800 362.0000 1.0000
14.4400 369.0000 1.0000
14.5000 389.0000 1.0000
14.5600 352.0000 1.0000
14.6200 343.0000 1.0000
14.6800 355.0000 1.0000
14.7400 324.0000 1.0000
14.8000 348.0000 1.0000
14.8600 316.0000 1.0000
14.9200 365.0000 1.0000
14.9800 336.0000 1.0000
15.0400 336.0000 1.0000
15.1000 348.0000 1.0000
15.1600 288.0000 1.0000
15.2200 360.0000 1.0000
15.2800 368.0000 1.0000
15.3400 377.0000 1.0000
15.4000 348.0000 1.0000
15.4600 329.0000 1.0000
15.5200 323.0000 1.0000
15.5800 325.0000 1.0000
15.6400 332.0000 1.0000
15.7000 307.0000 1.0000
15.7600 290.0000 1.0000
15.8200 328.0000 1.0000
15.8800 295.0000 1.0000
15.9400 335.0000 1.0000
16.0000 336.0000 1.0000
16.0600 334.0000 1.0000
16.1200 321.0000 1.0000
16.1800 328.0000 1.0000
16.2400 343.0000 1.0000
16.3000 319.0000 1.0000
16.3600 323.0000 1.0000
16.4200 298.0000 1.0000
16.4800 350.0000 1.0000
16.5400 290.0000 1.0000
16.6000 311.0000 1.0000
16.6600 331.0000 1.0000
16.7200 306.0000 1.0000
16.7800 301.0000 1.0000
16.8400 295.0000 1.0000
16.9000 327.0000 1.0000
16.9600 330.0000 1.0000
17.0200 325.0000 1.0000
17.0800 302.0000 1.0000
17.1400 339.0000 1.0000
17.2000 293.0000 1.0000
17.2600 294.0000 1.0000
17.3200 318.0000 1.0000
17.3800 313.0000 1.0000
17.4400 288.0000 1.0000
17.5000 274.0000 1.0000
17.5600 282.0000 1.0000
17.6200 298.0000 1.0000
17.6800 318.0000 1.0000
17.7400 316.0000 1.0000
17.8000 290.0000 1.0000
17.8600 301.0000 1.0000
17.9200 304.0000 1.0000
17.9800 268.0000 1.0000
18.0400 328.0000 1.0000
18.1000 266.0000 1.0000
18.1600 279.0000 1.0000
18.2200 289.0000 1.0000
18.2800 319.0000 1.0000
18.3400 258.0000 1.0000
18.4000 294.0000 1.0000
18.4600 267.0000 1.0000
18.5200 306.0000 1.0000
18.5800 292.0000 1.0000
18.6400 302.0000 1.0000
18.7000 281.0000 1.0000
18.7600 302.0000 1.0000
18.8200 279.0000 1.0000
18.8800 303.0000 1.0000
18.9400 272.0000 1.0000
19.0000 270.0000 1.0000
19.0600 269.0000 1.0000
19.1200 276.0000 1.0000
19.1800 285.0000 1.0000
19.2400 309.0000 1.0000
19.3000 276.0000 1.0000
19.3600 269.0000 1.0000
19.4200 279.0000 1.0000
19.4800 253.0000 1.0000
19.5400 243.0000 1.0000
19.6000 290.0000 1.0000
19.6600 245.0000 1.0000
19.7200 275.0000 1.0000
19.7800 287.0000 1.0000
19.8400 272.0000 1.0000
19.9000 304.0000 1.0000
19.9600 268.0000 1.0000
20.0200 268.0000 1.0000
20.0800 301.0000 1.0000
20.1400 268.0000 1.0000
20.2000 263.0000 1.0000
20.2600 298.0000 1.0000
20.3200 279.0000 1.0000
20.3800 282.0000 1.0000
20.4400 275.0000 1.0000
20.5000 287.0000 1.0000
20.5600 288.0000 1.0000
20.6200 280.0000 1.0000
20.6800 282.0000 1.0000
20.7400 289.0000 1.0000
20.8000 266.0000 1.0000
20.8600 305.0000 1.0000
20.9200 263.0000 1.0000
20.9800 288.0000 1.0000
21.0400 294.0000 1.0000
21.1000 286.0000 1.0000
21.1600 269.0000 1.0000
21.2200 281.0000 1.0000
21.2800 267.0000 1.0000
21.3400 268.0000 1.0000
21.4000 265.0000 1.0000
21.4600 280.0000 1.0000
21.5200 297.0000 1.0000
21.5800 299.0000 1.0000
21.6400 280.0000 1.0000
21.7000 304.0000 1.0000
21.7600 281.0000 1.0000
21.8200 280.0000 1.0000
21.8800 271.0000 1.0000
21.9400 250.0000 1.0000
22.0000 304.0000 1.0000
22.0600 270.0000 1.0000
22.1200 281.0000 1.0000
22.1800 260.0000 1.0000
22.2400 247.0000 1.0000
22.3000 288.0000 1.0000
22.3600 247.0000 1.0000
22.4200 262.0000 1.0000
22.4800 284.0000 1.0000
22.5400 292.0000 1.0000
22.6000 288.0000 1.0000
22.6600 305.0000 1.0000
22.7200 273.0000 1.0000
22.7800 315.0000 1.0000
22.8400 250.0000 1.0000
22.9000 296.0000 1.0000
22.9600 258.0000 1.0000
23.0200 296.0000 1.0000
23.0800 245.0000 1.0000
23.1400 256.0000 1.0000
23.2000 262.0000 1.0000
23.2600 293.0000 1.0000
23.3200 251.0000 1.0000
23.3800 304.0000 1.0000
23.4400 290.0000 1.0000
23.5000 303.0000 1.0000
23.5600 280.0000 1.0000
23.6200 306.0000 1.0000
23.6800 260.0000 1.0000
23.7400 296.0000 1.0000
23.8000 297.0000 1.0000
23.8600 299.0000 1.0000
23.9200 296.0000 1.0000
23.9800 316.0000 1.0000
24.0400 286.0000 1.0000
24.1000 368.0000 1.0000
24.1600 370.0000 1.0000
24.2200 330.0000 1.0000
24.2800 303.0000 1.0000
24.3400 284.0000 1.0000
24.4000 289.0000 1.0000
24.4600 275.0000 1.0000
24.5200 302.0000 1.0000
24.5800 284.0000 1.0000
24.6400 295.0000 1.0000
24.7000 292.0000 1.0000
24.7600 267.0000 1.0000
24.8200 293.0000 1.0000
24.8800 279.0000 1.0000
24.9400 270.0000 1.0000
25.0000 257.0000 1.0000
25.0600 260.0000 1.0000
25.1200 294.0000 1.0000
25.1800 286.0000 1.0000
25.2400 270.0000 1.0000
25.3000 309.0000 1.0000
25.3600 325.0000 1.0000
25.4200 261.0000 1.0000
25.4800 277.0000 1.0000
25.5400 283.0000 1.0000
25.6000 254.0000 1.0000
25.6600 302.0000 1.0000
25.7200 282.0000 1.0000
25.7800 269.0000 1.0000
25.8400 283.0000 1.0000
25.9000 280.0000 1.0000
25.9600 287.0000 1.0000
26.0200 281.0000 1.0000
26.0800 246.0000 1.0000
26.1400 291.0000 1.0000
26.2000 284.0000 1.0000
26.2600 261.0000 1.0000
26.3200 313.0000 1.0000
26.3800 297.0000 1.0000
26.4400 254.0000 1.0000
26.5000 285.0000 1.0000
26.5600 318.0000 1.0000
26.6200 325.0000 1.0000
26.6800 310.0000 1.0000
26.7400 280.0000 1.0000
26.8000 258.0000 1.0000
26.8600 288.0000 1.0000
26.9200 260.0000 1.0000
26.9800 246.0000 1.0000
27.0400 292.0000 1.0000
27.1000 277.0000 1.0000
27.1600 288.0000 1.0000
27.2200 295.0000 1.0000
27.2800 261.0000 1.0000
27.3400 296.0000 1.0000
27.4000 248.0000 1.0000
27.4600 263.0000 1.0000
27.5200 285.0000 1.0000
27.5800 293.0000 1.0000
27.6400 301.0000 1.0000
27.7000 244.0000 1.0000
27.7600 278.0000 1.0000
27.8200 274.0000 1.0000
27.8800 266.0000 1.0000
27.9400 281.0000 1.0000
28.0000 276.0000 1.0000
28.0600 269.0000 1.0000
28.1200 262.0000 1.0000
28.1800 267.0000 1.0000
28.2400 258.0000 1.0000
28.3000 306.0000 1.0000
28.3600 258.0000 1.0000
28.4200 254.0000 1.0000
28.4800 251.0000 1.0000
28.5400 272.0000 1.0000
28.6000 297.0000 1.0000
28.6600 266.0000 1.0000
28.7200 259.0000 1.0000
28.7800 259.0000 1.0000
28.8400 297.0000 1.0000
28.9000 289.0000 1.0000
28.9600 275.0000 1.0000
29.0200 287.0000 1.0000
29.0800 266.0000 1.0000
29.1400 260.0000 1.0000
29.2000 268.0000 1.0000
29.2600 254.0000 1.0000
29.3200 284.0000 1.0000
29.3800 278.0000 1.0000
29.4400 262.0000 1.0000
29.5000 279.0000 1.0000
29.5600 274.0000 1.0000
29.6200 273.0000 1.0000
29.6800 279.0000 1.0000
29.7400 265.0000 1.0000
29.8000 295.0000 1.0000
29.8600 282.0000 1.0000
29.9200 277.0000 1.0000
29.9800 276.0000 1.0000
30.0400 280.0000 1.0000
30.1000 284.0000 1.0000
30.1600 290.0000 1.0000
30.2200 268.0000 1.0000
30.2800 286.0000 1.0000
30.3400 307.0000 1.0000
30.4000 283.0000 1.0000
30.4600 269.0000 1.0000
30.5200 277.0000 1.0000
30.5800 285.0000 1.0000
30.6400 292.0000 1.0000
30.7000 303.0000 1.0000
30.7600 283.0000 1.0000
30.8200 322.0000 1.0000
30.8800 394.0000 1.0000
30.9400 363.0000 1.0000
31.0000 335.0000 1.0000
31.0600 321.0000 1.0000
31.1200 287.0000 1.0000
31.1800 292.0000 1.0000
31.2400 288.0000 1.0000
31.3000 273.0000 1.0000
31.3600 245.0000 1.0000
31.4200 274.0000 1.0000
31.4800 294.0000 1.0000
31.5400 289.0000 1.0000
31.6000 253.0000 1.0000
31.6600 258.0000 1.0000
31.7200 287.0000 1.0000
31.7800 272.0000 1.0000
31.8400 275.0000 1.0000
31.9000 291.0000 1.0000
31.9600 286.0000 1.0000
32.0200 278.0000 1.0000
32.0800 288.0000 1.0000
32.1400 272.0000 1.0000
32.2000 308.0000 1.0000
32.2600 303.0000 1.0000
32.3200 296.0000 1.0000
32.3800 291.0000 1.0000
32.4400 291.0000 1.0000
32.5000 322.0000 1.0000
32.5600 318.0000 1.0000
32.6200 302.0000 1.0000
32.6800 275.0000 1.0000
32.7400 316.0000 1.0000
32.8000 313.0000 1.0000
32.8600 296.0000 1.0000
32.9200 373.0000 1.0000
32.9800 424.0000 1.0000
33.0400 469.0000 1.0000
33.1000 527.0000 1.0000
33.1600 583.0000 1.0000
33.2200 501.0000 1.0000
33.2800 449.0000 1.0000
33.3400 339.0000 1.0000
33.4000 326.0000 1.0000
33.4600 301.0000 1.0000
33.5200 274.0000 1.0000
33.5800 313.0000 1.0000
33.6400 297.0000 1.0000
33.7000 294.0000 1.0000
33.7600 310.0000 1.0000
33.8200 302.0000 1.0000
33.8800 265.0000 1.0000
33.9400 249.0000 1.0000
34.0000 298.0000 1.0000
34.0600 289.0000 1.0000
34.1200 275.0000 1.0000
34.1800 276.0000 1.0000
34.2400 269.0000 1.0000
34.3000 276.0000 1.0000
34.3600 272.0000 1.0000
34.4200 289.0000 1.0000
34.4800 279.0000 1.0000
34.5400 289.0000 1.0000
34.6000 287.0000 1.0000
34.6600 273.0000 1.0000
34.7200 249.0000 1.0000
34.7800 262.0000 1.0000
34.8400 248.0000 1.0000
34.9000 259.0000 1.0000
34.9600 276.0000 1.0000
35.0200 279.0000 1.0000
35.0800 293.0000 1.0000
35.1400 301.0000 1.0000
35.2000 324.0000 1.0000
35.2600 284.0000 1.0000
35.3200 295.0000 1.0000
35.3800 318.0000 1.0000
35.4400 308.0000 1.0000
35.5000 351.0000 1.0000
35.5600 409.0000 1.0000
35.6200 396.0000 1.0000
35.6800 387.0000 1.0000
35.7400 349.0000 1.0000
35.8000 280.0000 1.0000
35.8600 277.0000 1.0000
35.9200 286.0000 1.0000
35.9800 285.0000 1.0000
36.0400 276.0000 1.0000
36.1000 288.0000 1.0000
36.1600 265.0000 1.0000
36.2200 284.0000 1.0000
36.2800 274.0000 1.0000
36.3400 249.0000 1.0000
36.4000 289.0000 1.0000
36.4600 291.0000 1.0000
36.5200 258.0000 1.0000
36.5800 270.0000 1.0000
36.6400 312.0000 1.0000
36.7000 263.0000 1.0000
36.7600 242.0000 1.0000
36.8200 283.0000 1.0000
36.8800 259.0000 1.0000
36.9400 249.0000 1.0000
37.0000 279.0000 1.0000
37.0600 277.0000 1.0000
37.1200 287.0000 1.0000
37.1800 294.0000 1.0000
37.2400 274.0000 1.0000
37.3000 286.0000 1.0000
37.3600 266.0000 1.0000
37.4200 285.0000 1.0000
37.4800 272.0000 1.0000
37.5400 273.0000 1.0000
37.6000 272.0000 1.0000
37.6600 291.0000 1.0000
37.7200 284.0000 1.0000
37.7800 281.0000 1.0000
37.8400 264.0000 1.0000
37.9000 286.0000 1.0000
37.9600 272.0000 1.0000
38.0200 260.0000 1.0000
38.0800 267.0000 1.0000
38.1400 275.0000 1.0000
38.2000 277.0000 1.0000
38.2600 302.0000 1.0000
38.3200 260.0000 1.0000
38.3800 250.0000 1.0000
38.4400 266.0000 1.0000
38.5000 270.0000 1.0000
38.5600 285.0000 1.0000
38.6200 277.0000 1.0000
38.6800 282.0000 1.0000
38.7400 265.0000 1.0000
38.8000 285.0000 1.0000
38.8600 259.0000 1.0000
38.9200 266.0000 1.0000
38.9800 316.0000 1.0000
39.0400 282.0000 1.0000
39.1000 291.0000 1.0000
39.1600 291.0000 1.0000
39.2200 290.0000 1.0000
39.2800 298.0000 1.0000
39.3400 267.0000 1.0000
39.4000 303.0000 1.0000
39.4600 290.0000 1.0000
39.5200 275.0000 1.0000
39.5800 272.0000 1.0000
39.6400 295.0000 1.0000
39.7000 309.0000 1.0000
39.7600 292.0000 1.0000
39.8200 306.0000 1.0000
39.8800 239.0000 1.0000
39.9400 287.0000 1.0000
40.0000 224.0000 1.0000
40.0600 278.0000 1.0000
40.1200 272.0000 1.0000
40.1800 300.0000 1.0000
40.2400 292.0000 1.0000
40.3000 274.0000 1.0000
40.3600 273.0000 1.0000
40.4200 278.0000 1.0000
40.4800 258.0000 1.0000
40.5400 267.0000 1.0000
40.6000 263.0000 1.0000
40.6600 278.0000 1.0000
40.7200 278.0000 1.0000
40.7800 306.0000 1.0000
40.8400 325.0000 1.0000
40.9000 324.0000 1.0000
40.9600 318.0000 1.0000
41.0200 288.0000 1.0000
41.0800 330.0000 1.0000
41.1400 294.0000 1.0000
41.2000 327.0000 1.0000
41.2600 320.0000 1.0000
41.3200 263.0000 1.0000
41.3800 271.0000 1.0000
41.4400 274.0000 1.0000
41.5000 303.0000 1.0000
41.5600 265.0000 1.0000
41.6200 275.0000 1.0000
41.6800 262.0000 1.0000
41.7400 282.0000 1.0000
41.8000 287.0000 1.0000
41.8600 260.0000 1.0000
41.9200 293.0000 1.0000
41.9800 256.0000 1.0000
42.0400 298.0000 1.0000
42.1000 294.0000 1.0000
42.1600 273.0000 1.0000
42.2200 304.0000 1.0000
42.2800 287.0000 1.0000
42.3400 299.0000 1.0000
42.4000 292.0000 1.0000
42.4600 251.0000 1.0000
42.5200 280.0000 1.0000
42.5800 308.0000 1.0000
42.6400 278.0000 1.0000
42.7000 276.0000 1.0000
42.7600 291.0000 1.0000
42.8200 279.0000 1.0000
42.8800 276.0000 1.0000
42.9400 282.0000 1.0000
43.0000 262.0000 1.0000
43.0600 298.0000 1.0000
43.1200 289.0000 1.0000
43.1800 289.0000 1.0000
43.2400 283.0000 1.0000
43.3000 268.0000 1.0000
43.3600 275.0000 1.0000
43.4200 277.0000 1.0000
43.4800 272.0000 1.0000
43.5400 272.0000 1.0000
43.6000 266.0000 1.0000
43.6600 297.0000 1.0000
43.7200 281.0000 1.0000
43.7800 291.0000 1.0000
43.8400 294.0000 1.0000
43.9000 315.0000 1.0000
43.9600 274.0000 1.0000
44.0200 279.0000 1.0000
44.0800 262.0000 1.0000
44.1400 270.0000 1.0000
44.2000 261.0000 1.0000
44.2600 245.0000 1.0000
44.3200 293.0000 1.0000
44.3800 258.0000 1.0000
44.4400 295.0000 1.0000
44.5000 277.0000 1.0000
44.5600 280.0000 1.0000
44.6200 305.0000 1.0000
44.6800 291.0000 1.0000
44.7400 276.0000 1.0000
44.8000 276.0000 1.0000
44.8600 297.0000 1.0000
44.9200 282.0000 1.0000
44.9800 259.0000 1.0000
45.0400 284.0000 1.0000
45.1000 241.0000 1.0000
45.1600 250.0000 1.0000
45.2200 284.0000 1.0000
45.2800 263.0000 1.0000
45.3400 270.0000 1.0000
45.4000 285.0000 1.0000
45.4600 282.0000 1.0000
45.5200 282.0000 1.0000
45.5800 283.0000 1.0000
45.6400 242.0000 1.0000
45.7000 260.0000 1.0000
45.7600 287.0000 1.0000
45.8200 291.0000 1.0000
45.8800 254.0000 1.0000
45.9400 289.0000 1.0000
46.0000 289.0000 1.0000
46.0600 286.0000 1.0000
46.1200 272.0000 1.0000
46.1800 249.0000 1.0000
46.2400 291.0000 1.0000
46.3000 254.0000 1.0000
46.3600 265.0000 1.0000
46.4200 283.0000 1.0000
46.4800 272.0000 1.0000
46.5400 290.0000 1.0000
46.6000 286.0000 1.0000
46.6600 263.0000 1.0000
46.7200 315.0000 1.0000
46.7800 291.0000 1.0000
46.8400 284.0000 1.0000
46.9000 270.0000 1.0000
46.9600 284.0000 1.0000
47.0200 292.0000 1.0000
47.0800 257.0000 1.0000
47.1400 277.0000 1.0000
47.2000 271.0000 1.0000
47.2600 266.0000 1.0000
47.3200 260.0000 1.0000
47.3800 249.0000 1.0000
47.4400 273.0000 1.0000
47.5000 261.0000 1.0000
47.5600 271.0000 1.0000
47.6200 299.0000 1.0000
47.6800 324.0000 1.0000
47.7400 265.0000 1.0000
47.8000 267.0000 1.0000
47.8600 276.0000 1.0000
47.9200 309.0000 1.0000
47.9800 289.0000 1.0000
48.0400 275.0000 1.0000
48.1000 266.0000 1.0000
48.1600 280.0000 1.0000
48.2200 258.0000 1.0000
48.2800 288.0000 1.0000
48.3400 282.0000 1.0000
48.4000 310.0000 1.0000
48.4600 285.0000 1.0000
48.5200 305.0000 1.0000
48.5800 269.0000 1.0000
48.6400 255.0000 1.0000
48.7000 274.0000 1.0000
48.7600 287.0000 1.0000
48.8200 277.0000 1.0000
48.8800 249.0000 1.0000
48.9400 274.0000 1.0000
49.0000 296.0000 1.0000
49.0600 259.0000 1.0000
49.1200 300.0000 1.0000
49.1800 278.0000 1.0000
49.2400 302.0000 1.0000
49.3000 319.0000 1.0000
49.3600 349.0000 1.0000
49.4200 333.0000 1.0000
49.4800 316.0000 1.0000
49.5400 346.0000 1.0000
49.6000 324.0000 1.0000
49.6600 294.0000 1.0000
49.7200 307.0000 1.0000
49.7800 272.0000 1.0000
49.8400 289.0000 1.0000
49.9000 305.0000 1.0000
49.9600 287.0000 1.0000
50.0200 265.0000 1.0000
50.0800 277.0000 1.0000
50.1400 267.0000 1.0000
50.2000 297.0000 1.0000
50.2600 275.0000 1.0000
50.3200 262.0000 1.0000
50.3800 296.0000 1.0000
50.4400 304.0000 1.0000
50.5000 304.0000 1.0000
50.5600 281.0000 1.0000
50.6200 299.0000 1.0000
50.6800 291.0000 1.0000
50.7400 263.0000 1.0000
50.8000 300.0000 1.0000
50.8600 250.0000 1.0000
50.9200 284.0000 1.0000
50.9800 302.0000 1.0000
51.0400 309.0000 1.0000
51.1000 283.0000 1.0000
51.1600 275.0000 1.0000
51.2200 280.0000 1.0000
51.2800 305.0000 1.0000
51.3400 294.0000 1.0000
51.4000 312.0000 1.0000
51.4600 286.0000 1.0000
51.5200 271.0000 1.0000
51.5800 261.0000 1.0000
51.6400 283.0000 1.0000
51.7000 277.0000 1.0000
51.7600 284.0000 1.0000
51.8200 287.0000 1.0000
51.8800 291.0000 1.0000
51.9400 247.0000 1.0000
52.0000 299.0000 1.0000
52.0600 304.0000 1.0000
52.1200 283.0000 1.0000
52.1800 268.0000 1.0000
52.2400 261.0000 1.0000
52.3000 268.0000 1.0000
52.3600 266.0000 1.0000
52.4200 283.0000 1.0000
52.4800 315.0000 1.0000
52.5400 281.0000 1.0000
52.6000 285.0000 1.0000
52.6600 267.0000 1.0000
52.7200 258.0000 1.0000
52.7800 258.0000 1.0000
52.8400 241.0000 1.0000
52.9000 293.0000 1.0000
52.9600 309.0000 1.0000
53.0200 284.0000 1.0000
53.0800 282.0000 1.0000
53.1400 290.0000 1.0000
53.2000 302.0000 1.0000
53.2600 290.0000 1.0000
53.3200 289.0000 1.0000
53.3800 274.0000 1.0000
53.4400 291.0000 1.0000
53.5000 285.0000 1.0000
53.5600 276.0000 1.0000
53.6200 274.0000 1.0000
53.6800 305.0000 1.0000
53.7400 270.0000 1.0000
53.8000 290.0000 1.0000
53.8600 324.0000 1.0000
53.9200 360.0000 1.0000
53.9800 398.0000 1.0000
54.0400 347.0000 1.0000
54.1000 369.0000 1.0000
54.1600 355.0000 1.0000
54.2200 333.0000 1.0000
54.2800 311.0000 1.0000
54.3400 315.0000 1.0000
54.4000 304.0000 1.0000
54.4600 290.0000 1.0000
54.5200 279.0000 1.0000
54.5800 274.0000 1.0000
54.6400 283.0000 1.0000
54.7000 275.0000 1.0000
54.7600 254.0000 1.0000
54.8200 311.0000 1.0000
54.8800 271.0000 1.0000
54.9400 270.0000 1.0000
55.0000 253.0000 1.0000
55.0600 302.0000 1.0000
55.1200 288.0000 1.0000
55.1800 273.0000 1.0000
55.2400 262.0000 1.0000
55.3000 301.0000 1.0000
55.3600 296.0000 1.0000
55.4200 286.0000 1.0000
55.4800 258.0000 1.0000
55.5400 301.0000 1.0000
55.6000 244.0000 1.0000
55.6600 276.0000 1.0000
55.7200 295.0000 1.0000
55.7800 259.0000 1.0000
55.8400 303.0000 1.0000
55.9000 279.0000 1.0000
55.9600 270.0000 1.0000
56.0200 276.0000 1.0000
56.0800 287.0000 1.0000
56.1400 282.0000 1.0000
56.2000 298.0000 1.0000
56.2600 319.0000 1.0000
56.3200 264.0000 1.0000
56.3800 254.0000 1.0000
56.4400 283.0000 1.0000
56.5000 272.0000 1.0000
56.5600 285.0000 1.0000
56.6200 275.0000 1.0000
56.6800 268.0000 1.0000
56.7400 253.0000 1.0000
56.8000 286.0000 1.0000
56.8600 264.0000 1.0000
56.9200 270.0000 1.0000
56.9800 286.0000 1.0000
57.0400 258.0000 1.0000
57.1000 276.0000 1.0000
57.1600 298.0000 1.0000
57.2200 277.0000 1.0000
57.2800 287.0000 1.0000
57.3400 286.0000 1.0000
57.4000 308.0000 1.0000
57.4600 299.0000 1.0000
57.5200 301.0000 1.0000
57.5800 350.0000 1.0000
57.6400 325.0000 1.0000
57.7000 275.0000 1.0000
57.7600 299.0000 1.0000
57.8200 271.0000 1.0000
57.8800 280.0000 1.0000
57.9400 275.0000 1.0000
58.0000 290.0000 1.0000
58.0600 253.0000 1.0000
58.1200 292.0000 1.0000
58.1800 267.0000 1.0000
58.2400 263.0000 1.0000
58.3000 281.0000 1.0000
58.3600 277.0000 1.0000
58.4200 264.0000 1.0000
58.4800 279.0000 1.0000
58.5400 282.0000 1.0000
58.6000 284.0000 1.0000
58.6600 288.0000 1.0000
58.7200 300.0000 1.0000
58.7800 276.0000 1.0000
58.8400 255.0000 1.0000
58.9000 285.0000 1.0000
58.9600 254.0000 1.0000
59.0200 280.0000 1.0000
59.0800 279.0000 1.0000
59.1400 266.0000 1.0000
59.2000 275.0000 1.0000
59.2600 285.0000 1.0000
59.3200 261.0000 1.0000
59.3800 271.0000 1.0000
59.4400 281.0000 1.0000
59.5000 268.0000 1.0000
59.5600 259.0000 1.0000
59.6200 284.0000 1.0000
59.6800 279.0000 1.0000
59.7400 271.0000 1.0000
59.8000 290.0000 1.0000
59.8600 274.0000 1.0000
59.9200 285.0000 1.0000
59.9800 279.0000 1.0000
60.0400 273.0000 1.0000
60.1000 289.0000 1.0000
60.1600 263.0000 1.0000
60.2200 284.0000 1.0000
60.2800 269.0000 1.0000
60.3400 301.0000 1.0000
60.4000 279.0000 1.0000
60.4600 259.0000 1.0000
60.5200 304.0000 1.0000
60.5800 261.0000 1.0000
60.6400 266.0000 1.0000
60.7000 263.0000 1.0000
60.7600 281.0000 1.0000
60.8200 259.0000 1.0000
60.8800 298.0000 1.0000
60.9400 284.0000 1.0000
61.0000 285.0000 1.0000
61.0600 274.0000 1.0000
61.1200 284.0000 1.0000
61.1800 298.0000 1.0000
61.2400 254.0000 1.0000
61.3000 233.0000 1.0000
61.3600 272.0000 1.0000
61.4200 266.0000 1.0000
61.4800 298.0000 1.0000
61.5400 265.0000 1.0000
61.6000 288.0000 1.0000
61.6600 249.0000 1.0000
61.7200 265.0000 1.0000
61.7800 264.0000 1.0000
61.8400 300.0000 1.0000
61.9000 296.0000 1.0000
61.9600 261.0000 1.0000
62.0200 306.0000 1.0000
62.0800 322.0000 1.0000
62.1400 295.0000 1.0000
62.2000 338.0000 1.0000
62.2600 315.0000 1.0000
62.3200 330.0000 1.0000
62.3800 326.0000 1.0000
62.4400 328.0000 1.0000
62.5000 322.0000 1.0000
62.5600 298.0000 1.0000
62.6200 296.0000 1.0000
62.6800 327.0000 1.0000
62.7400 284.0000 1.0000
62.8000 288.0000 1.0000
62.8600 306.0000 1.0000
62.9200 285.0000 1.0000
62.9800 299.0000 1.0000
63.0400 285.0000 1.0000
63.1000 288.0000 1.0000
63.1600 267.0000 1.0000
63.2200 306.0000 1.0000
63.2800 277.0000 1.0000
63.3400 295.0000 1.0000
63.4000 267.0000 1.0000
63.4600 288.0000 1.0000
63.5200 289.0000 1.0000
63.5800 265.0000 1.0000
63.6400 274.0000 1.0000
63.7000 257.0000 1.0000
63.7600 286.0000 1.0000
63.8200 296.0000 1.0000
63.8800 285.0000 1.0000
63.9400 334.0000 1.0000
64.0000 286.0000 1.0000
64.0600 294.0000 1.0000
64.1200 303.0000 1.0000
64.1800 304.0000 1.0000
64.2400 299.0000 1.0000
64.3000 280.0000 1.0000
64.3600 282.0000 1.0000
64.4200 297.0000 1.0000
64.4800 265.0000 1.0000
64.5400 281.0000 1.0000
64.6000 262.0000 1.0000
64.6600 275.0000 1.0000
64.7200 256.0000 1.0000
64.7800 308.0000 1.0000
64.8400 308.0000 1.0000
64.9000 273.0000 1.0000
64.9600 260.0000 1.0000
65.0200 261.0000 1.0000
65.0800 292.0000 1.0000
65.1400 291.0000 1.0000
65.2000 300.0000 1.0000
65.2600 314.0000 1.0000
65.3200 270.0000 1.0000
65.3800 275.0000 1.0000
65.4400 296.0000 1.0000
65.5000 269.0000 1.0000
65.5600 287.0000 1.0000
65.6200 264.0000 1.0000
65.6800 243.0000 1.0000
65.7400 282.0000 1.0000
65.8000 284.0000 1.0000
65.8600 278.0000 1.0000
65.9200 277.0000 1.0000
65.9800 268.0000 1.0000
66.0400 292.0000 1.0000
66.1000 288.0000 1.0000
66.1600 246.0000 1.0000
66.2200 283.0000 1.0000
66.2800 293.0000 1.0000
66.3400 268.0000 1.0000
66.4000 212.0000 1.0000
66.4600 293.0000 1.0000
66.5200 252.0000 1.0000
66.5800 274.0000 1.0000
66.6400 301.0000 1.0000
66.7000 251.0000 1.0000
66.7600 276.0000 1.0000
66.8200 294.0000 1.0000
66.8800 294.0000 1.0000
66.9400 294.0000 1.0000
67.0000 281.0000 1.0000
67.0600 258.0000 1.0000
67.1200 290.0000 1.0000
67.1800 269.0000 1.0000
67.2400 286.0000 1.0000
67.3000 264.0000 1.0000
67.3600 295.0000 1.0000
67.4200 317.0000 1.0000
67.4800 285.0000 1.0000
67.5400 290.0000 1.0000
67.6000 294.0000 1.0000
67.6600 312.0000 1.0000
67.7200 272.0000 1.0000
67.7800 282.0000 1.0000
67.8400 288.0000 1.0000
67.9000 264.0000 1.0000
67.9600 274.0000 1.0000
68.0200 299.0000 1.0000
68.0800 292.0000 1.0000
68.1400 273.0000 1.0000
68.2000 284.0000 1.0000
68.2600 271.0000 1.0000
68.3200 275.0000 1.0000
68.3800 285.0000 1.0000
68.4400 285.0000 1.0000
68.5000 268.0000 1.0000
68.5600 266.0000 1.0000
68.6200 274.0000 1.0000
68.6800 270.0000 1.0000
68.7400 294.0000 1.0000
68.8000 228.0000 1.0000
68.8600 290.0000 1.0000
68.9200 290.0000 1.0000
68.9800 282.0000 1.0000
69.0400 302.0000 1.0000
69.1000 280.0000 1.0000
69.1600 292.0000 1.0000
69.2200 285.0000 1.0000
69.2800 292.0000 1.0000
69.3400 275.0000 1.0000
69.4000 327.0000 1.0000
69.4600 255.0000 1.0000
69.5200 281.0000 1.0000
69.5800 287.0000 1.0000
69.6400 240.0000 1.0000
69.7000 293.0000 1.0000
69.7600 284.0000 1.0000
69.8200 288.0000 1.0000
69.8800 285.0000 1.0000
69.9400 280.0000 1.0000
70.0000 293.0000 1.0000
70.0600 290.0000 1.0000
70.1200 291.0000 1.0000
70.1800 258.0000 1.0000
70.2400 267.0000 1.0000
70.3000 304.0000 1.0000
70.3600 296.0000 1.0000
70.4200 267.0000 1.0000
70.4800 258.0000 1.0000
70.5400 296.0000 1.0000
70.6000 258.0000 1.0000
70.6600 247.0000 1.0000
70.7200 263.0000 1.0000
70.7800 306.0000 1.0000
70.8400 302.0000 1.0000
70.9000 290.0000 1.0000
70.9600 268.0000 1.0000
71.0200 287.0000 1.0000
71.0800 274.0000 1.0000
71.1400 270.0000 1.0000
71.2000 294.0000 1.0000
71.2600 279.0000 1.0000
71.3200 271.0000 1.0000
71.3800 253.0000 1.0000
71.4400 286.0000 1.0000
71.5000 249.0000 1.0000
71.5600 288.0000 1.0000
71.6200 279.0000 1.0000
71.6800 265.0000 1.0000
71.7400 325.0000 1.0000
71.8000 275.0000 1.0000
71.8600 297.0000 1.0000
71.9200 285.0000 1.0000
71.9800 312.0000 1.0000
72.0400 319.0000 1.0000
72.1000 297.0000 1.0000
72.1600 276.0000 1.0000
72.2200 301.0000 1.0000
72.2800 313.0000 1.0000
72.3400 292.0000 1.0000
72.4000 256.0000 1.0000
72.4600 282.0000 1.0000
72.5200 276.0000 1.0000
72.5800 280.0000 1.0000
72.6400 282.0000 1.0000
72.7000 318.0000 1.0000
72.7600 293.0000 1.0000
72.8200 276.0000 1.0000
72.8800 287.0000 1.0000
72.9400 305.0000 1.0000
73.0000 278.0000 1.0000
73.0600 278.0000 1.0000
73.1200 285.0000 1.0000
73.1800 276.0000 1.0000
73.2400 276.0000 1.0000
73.3000 295.0000 1.0000
73.3600 284.0000 1.0000
73.4200 244.0000 1.0000
73.4800 302.0000 1.0000
73.5400 282.0000 1.0000
73.6000 279.0000 1.0000
73.6600 285.0000 1.0000
73.7200 284.0000 1.0000
73.7800 258.0000 1.0000
73.8400 267.0000 1.0000
73.9000 278.0000 1.0000
73.9600 284.0000 1.0000
74.0200 267.0000 1.0000
74.0800 281.0000 1.0000
74.1400 275.0000 1.0000
74.2000 282.0000 1.0000
74.2600 285.0000 1.0000
74.3200 244.0000 1.0000
74.3800 282.0000 1.0000
74.4400 263.0000 1.0000
74.5000 304.0000 1.0000
74.5600 295.0000 1.0000
74.6200 272.0000 1.0000
74.6800 287.0000 1.0000
74.7400 250.0000 1.0000
74.8000 286.0000 1.0000
74.8600 294.0000 1.0000
74.9200 290.0000 1.0000
74.9800 270.0000 1.0000
75.0400 288.0000 1.0000
75.1000 291.0000 1.0000
75.1600 278.0000 1.0000
75.2200 282.0000 1.0000
75.2800 256.0000 1.0000
75.3400 297.0000 1.0000
75.4000 289.0000 1.0000
75.4600 300.0000 1.0000
75.5200 263.0000 1.0000
75.5800 267.0000 1.0000
75.6400 300.0000 1.0000
75.7000 285.0000 1.0000
75.7600 296.0000 1.0000
75.8200 255.0000 1.0000
75.8800 300.0000 1.0000
75.9400 281.0000 1.0000
76.0000 273.0000 1.0000
76.0600 261.0000 1.0000
76.1200 259.0000 1.0000
76.1800 281.0000 1.0000
76.2400 276.0000 1.0000
76.3000 288.0000 1.0000
76.3600 265.0000 1.0000
76.4200 282.0000 1.0000
76.4800 296.0000 1.0000
76.5400 260.0000 1.0000
76.6000 278.0000 1.0000
76.6600 279.0000 1.0000
76.7200 289.0000 1.0000
76.7800 280.0000 1.0000
76.8400 283.0000 1.0000
76.9000 285.0000 1.0000
76.9600 271.0000 1.0000
77.0200 285.0000 1.0000
77.0800 292.0000 1.0000
77.1400 291.0000 1.0000
77.2000 280.0000 1.0000
77.2600 266.0000 1.0000
77.3200 265.0000 1.0000
77.3800 315.0000 1.0000
77.4400 286.0000 1.0000
77.5000 261.0000 1.0000
77.5600 242.0000 1.0000
77.6200 293.0000 1.0000
77.6800 284.0000 1.0000
77.7400 266.0000 1.0000
77.8000 277.0000 1.0000
77.8600 275.0000 1.0000
77.9200 266.0000 1.0000
77.9800 273.0000 1.0000
78.0400 287.0000 1.0000
78.1000 282.0000 1.0000
78.1600 287.0000 1.0000
78.2200 295.0000 1.0000
78.2800 263.0000 1.0000
78.3400 276.0000 1.0000
78.4000 283.0000 1.0000
78.4600 278.0000 1.0000
78.5200 269.0000 1.0000
78.5800 262.0000 1.0000
78.6400 293.0000 1.0000
78.7000 278.0000 1.0000
78.7600 275.0000 1.0000
78.8200 278.0000 1.0000
78.8800 308.0000 1.0000
78.9400 280.0000 1.0000
79.0000 270.0000 1.0000
79.0600 290.0000 1.0000
79.1200 288.0000 1.0000
79.1800 285.0000 1.0000
79.2400 302.0000 1.0000
79.3000 233.0000 1.0000
79.3600 249.0000 1.0000
79.4200 263.0000 1.0000
79.4800 274.0000 1.0000
79.5400 255.0000 1.0000
79.6000 288.0000 1.0000
79.6600 294.0000 1.0000
79.7200 264.0000 1.0000
79.7800 249.0000 1.0000
79.8400 256.0000 1.0000
79.9000 294.0000 1.0000
79.9600 266.0000 1.0000
80.0200 284.0000 1.0000
80.0800 269.0000 1.0000
80.1400 286.0000 1.0000
80.2000 296.0000 1.0000
80.2600 254.0000 1.0000
80.3200 261.0000 1.0000
80.3800 285.0000 1.0000
80.4400 328.0000 1.0000
80.5000 244.0000 1.0000
80.5600 293.0000 1.0000
80.6200 273.0000 1.0000
80.6800 281.0000 1.0000
80.7400 276.0000 1.0000
80.8000 303.0000 1.0000
80.8600 278.0000 1.0000
80.9200 303.0000 1.0000
80.9800 291.0000 1.0000
81.0400 283.0000 1.0000
81.1000 282.0000 1.0000
81.1600 278.0000 1.0000
81.2200 257.0000 1.0000
81.2800 273.0000 1.0000
81.3400 254.0000 1.0000
81.4000 313.0000 1.0000
81.4600 291.0000 1.0000
81.5200 278.0000 1.0000
81.5800 295.0000 1.0000
81.6400 279.0000 1.0000
81.7000 270.0000 1.0000
81.7600 286.0000 1.0000
81.8200 299.0000 1.0000
81.8800 276.0000 1.0000
81.9400 251.0000 1.0000
82.0000 277.0000 1.0000
82.0600 281.0000 1.0000
82.1200 264.0000 1.0000
82.1800 276.0000 1.0000
82.2400 282.0000 1.0000
82.3000 270.0000 1.0000
82.3600 296.0000 1.0000
82.4200 297.0000 1.0000
82.4800 296.0000 1.0000
82.5400 268.0000 1.0000
82.6000 275.0000 1.0000
82.6600 272.0000 1.0000
82.7200 273.0000 1.0000
82.7800 296.0000 1.0000
82.8400 252.0000 1.0000
82.9000 270.0000 1.0000
82.9600 267.0000 1.0000
83.0200 304.0000 1.0000
83.0800 297.0000 1.0000
83.1400 261.0000 1.0000
83.2000 264.0000 1.0000
83.2600 256.0000 1.0000
83.3200 264.0000 1.0000
83.3800 277.0000 1.0000
83.4400 294.0000 1.0000
83.5000 255.0000 1.0000
83.5600 263.0000 1.0000
83.6200 277.0000 1.0000
83.6800 289.0000 1.0000
83.7400 250.0000 1.0000
83.8000 245.0000 1.0000
83.8600 299.0000 1.0000
83.9200 264.0000 1.0000
83.9800 259.0000 1.0000
84.0400 259.0000 1.0000
84.1000 264.0000 1.0000
84.1600 319.0000 1.0000
84.2200 293.0000 1.0000
84.2800 288.0000 1.0000
84.3400 245.0000 1.0000
84.4000 291.0000 1.0000
84.4600 278.0000 1.0000
84.5200 260.0000 1.0000
84.5800 269.0000 1.0000
84.6400 317.0000 1.0000
84.7000 280.0000 1.0000
84.7600 253.0000 1.0000
84.8200 316.0000 1.0000
84.8800 327.0000 1.0000
84.9400 274.0000 1.0000
85.0000 291.0000 1.0000
85.0600 333.0000 1.0000
85.1200 284.0000 1.0000
85.1800 292.0000 1.0000
85.2400 292.0000 1.0000
85.3000 283.0000 1.0000
85.3600 273.0000 1.0000
85.4200 266.0000 1.0000
85.4800 278.0000 1.0000
85.5400 265.0000 1.0000
85.6000 247.0000 1.0000
85.6600 277.0000 1.0000
85.7200 276.0000 1.0000
85.7800 295.0000 1.0000
85.8400 303.0000 1.0000
85.9000 285.0000 1.0000
85.9600 230.0000 1.0000
86.0200 274.0000 1.0000
86.0800 271.0000 1.0000
86.1400 252.0000 1.0000
86.2000 289.0000 1.0000
86.2600 260.0000 1.0000
86.3200 249.0000 1.0000
86.3800 293.0000 1.0000
86.4400 258.0000 1.0000
86.5000 286.0000 1.0000
86.5600 318.0000 1.0000
86.6200 273.0000 1.0000
86.6800 273.0000 1.0000
86.7400 268.0000 1.0000
86.8000 267.0000 1.0000
86.8600 248.0000 1.0000
86.9200 271.0000 1.0000
86.9800 259.0000 1.0000
87.0400 274.0000 1.0000
87.1000 282.0000 1.0000
87.1600 269.0000 1.0000
87.2200 272.0000 1.0000
87.2800 265.0000 1.0000
87.3400 249.0000 1.0000
87.4000 283.0000 1.0000
87.4600 264.0000 1.0000
87.5200 264.0000 1.0000
87.5800 259.0000 1.0000
87.6400 291.0000 1.0000
87.7000 275.0000 1.0000
87.7600 245.0000 1.0000
87.8200 270.0000 1.0000
87.8800 292.0000 1.0000
87.9400 267.0000 1.0000
88.0000 256.0000 1.0000
88.0600 299.0000 1.0000
88.1200 296.0000 1.0000
88.1800 303.0000 1.0000
88.2400 272.0000 1.0000
88.3000 298.0000 1.0000
88.3600 266.0000 1.0000
88.4200 297.0000 1.0000
88.4800 303.0000 1.0000
88.5400 260.0000 1.0000
88.6000 298.0000 1.0000
88.6600 324.0000 1.0000
88.7200 268.0000 1.0000
88.7800 250.0000 1.0000
88.8400 281.0000 1.0000
88.9000 282.0000 1.0000
88.9600 258.0000 1.0000
89.0200 264.0000 1.0000
89.0800 267.0000 1.0000
89.1400 257.0000 1.0000
89.2000 270.0000 1.0000
89.2600 265.0000 1.0000
89.3200 278.0000 1.0000
89.3800 259.0000 1.0000
89.4400 262.0000 1.0000
89.5000 262.0000 1.0000
89.5600 267.0000 1.0000
89.6200 308.0000 1.0000
89.6800 275.0000 1.0000
89.7400 269.0000 1.0000
89.8000 236.0000 1.0000
89.8600 288.0000 1.0000
89.9200 263.0000 1.0000
89.9800 249.0000 1.0000
90.0000 293.0000 1.0000
*RAS_INT_END
*RAS_DATA_END