File: XRD_source_data/Magnetite.ras
*RAS_DATA_START
*RAS_HEADER_START
*DISP_FMT_X "%.2f"
*DISP_FMT_Y "%.0f"
*DISP_FULLSCALE "1434.0000000000"
*DISP_LINE_COLOR "255.0000000000"
*DISP_LINE_STYLE "0.0000000000"
*DISP_LINE_WIDTH "0.2500000000"
*DISP_NOTE "Collected Data-3"
*DISP_OFFSET_Y "0.0000000000"
*DISP_PEAKSEARCH_UNIT_Y "COUNTS"
*DISP_RANGE_BOTTOM "0.0000000000"
*DISP_RANGE_LEFT "10.0000000000"
*DISP_RANGE_LOGCUTOFF "0.0100000000"
*DISP_RANGE_RIGHT "90.0000000000"
*DISP_RANGE_TOP "1434.0000000000"
*DISP_SCALE_MODE_Y "0.0000000000"
*DISP_TAB_NAME "Theta/2-Theta"
*DISP_TITLE_Y "Intensity"
*DISP_UNIT_Y "COUNTS"
*DISP_WINDOW_NAME "MSG_MACROENGINE"
*FILE_COMMENT " "
*FILE_MD5 ""
*FILE_MEMO " "
*FILE_OPERATOR "Administrator"
*FILE_PART_ID "MEAS_PBEA_00223"
*FILE_SAMPLE "Magnetite"
*FILE_TYPE "RAS_RAW"
*FILE_USERGROUP "System Manager"
*FILE_VERSION "1.0000000000"
*HW_ATTACHMENT_ID "ATT1031"
*HW_ATTACHMENT_NAME "6サンプルチェンジャ|ASC-6"
*HW_COUNTER_ID-0 "CUT0021"
*HW_COUNTER_ID-1 "CUT0020"
*HW_COUNTER_ID-2 "CUT0020"
*HW_COUNTER_ID-3 "CMC0021"
*HW_COUNTER_NAME-0 "SC-70|SC-70"
*HW_COUNTER_NAME-1 "None|None"
*HW_COUNTER_NAME-2 "None|None"
*HW_COUNTER_NAME-3 "検出器モノクロメータ|Detector monochromator"
*HW_COUNTER_SELECT_NAME "SC-70|SC-70"
*HW_ECP_HV "714.0000000000"
*HW_ECP_HV_UNIT "V"
*HW_GONIOMETER_ID "GON0070"
*HW_GONIOMETER_NAME "MiniFlex 300/600|MiniFlex 300/600"
*HW_GONIOMETER_RADIUS-0 "79.0"
*HW_GONIOMETER_RADIUS-1 "91.5"
*HW_GONIOMETER_RADIUS-2 "150.0"
*HW_GONIOMETER_RADIUS-3 "0"
*HW_GONIOMETER_RADIUS-4 "103.4"
*HW_GONIOMETER_RADIUS-5 "150.0"
*HW_GONIOMETER_RADIUS-6 "46.6"
*HW_GONIOMETER_RADIUS-7 "160.0"
*HW_I_OPT_ID-0 "ISL0021"
*HW_I_OPT_ID-1 "ISO0021"
*HW_I_OPT_NAME-0 "発散スリット|Divergence slit"
*HW_I_OPT_NAME-1 "入射平行スリット|Incident parallel slit"
*HW_R_ATTENUATER_AUTOMODE "0"
*HW_R_OPT_ID-0 "RSS0021"
*HW_R_OPT_ID-1 "RSO0021"
*HW_R_OPT_ID-2 "RRS0021"
*HW_R_OPT_NAME-0 "散乱スリット|Scattering slit"
*HW_R_OPT_NAME-1 "受光平行スリット|Receiving soller slit"
*HW_R_OPT_NAME-2 "受光スリット|Receiving slit"
*HW_SAMPLE_HOLDER_ID "SMP0000"
*HW_SAMPLE_HOLDER_NAME "無し|None"
*HW_XG_CURRENT_MAX "50"
*HW_XG_CURRENT_MIN "2"
*HW_XG_CURRENT_RESOLUTION "2"
*HW_XG_CURRENT_UNIT "mA"
*HW_XG_FOCUS "1mm x 10mm"
*HW_XG_FOCUS_TYPE "Normal"
*HW_XG_ID "1062"
*HW_XG_NAME "300W/600W 封入管-A|300W/600W Sealed tube-A"
*HW_XG_TARGET_ATOMIC_NUMBER "29.0000000000"
*HW_XG_TARGET_NAME "Cu"
*HW_XG_TYPE "Compact"
*HW_XG_VOLTAGE_MAX "60"
*HW_XG_VOLTAGE_MIN "20"
*HW_XG_VOLTAGE_RESOLUTION "2"
*HW_XG_VOLTAGE_UNIT "kV"
*HW_XG_WATT_MAX "2.000"
*HW_XG_WATT_UNIT "kW"
*HW_XG_WAVE_LENGTH_ALPHA1 "1.540593"
*HW_XG_WAVE_LENGTH_ALPHA2 "1.544414"
*HW_XG_WAVE_LENGTH_BETA "1.392250"
*MEAS_COND_AXIS_NAME-0 "Theta/2-Theta"
*MEAS_COND_AXIS_NAME-1 "Spin"
*MEAS_COND_AXIS_NAME-2 "Change"
*MEAS_COND_AXIS_NAME-3 "Soller(inc.)"
*MEAS_COND_AXIS_NAME-4 "IHS"
*MEAS_COND_AXIS_NAME-5 "DS"
*MEAS_COND_AXIS_NAME-6 "SS"
*MEAS_COND_AXIS_NAME-7 "Soller(rec.)"
*MEAS_COND_AXIS_NAME-8 "RS"
*MEAS_COND_AXIS_NAME-9 "Filter"
*MEAS_COND_AXIS_NAME-10 "Monochromator"
*MEAS_COND_AXIS_NAME-11 "HV"
*MEAS_COND_AXIS_NAME-12 "PHA"
*MEAS_COND_AXIS_NAME_INTERNAL-0 "TwoThetaTheta"
*MEAS_COND_AXIS_NAME_INTERNAL-1 "Spin"
*MEAS_COND_AXIS_NAME_INTERNAL-2 "Change"
*MEAS_COND_AXIS_NAME_INTERNAL-3 "IncidentSollerSlit"
*MEAS_COND_AXIS_NAME_INTERNAL-4 "IncidentAxdSlit"
*MEAS_COND_AXIS_NAME_INTERNAL-5 "IncidentSlitBox"
*MEAS_COND_AXIS_NAME_INTERNAL-6 "ReceivingSlitBox1"
*MEAS_COND_AXIS_NAME_INTERNAL-7 "ReceivingSollerSlit"
*MEAS_COND_AXIS_NAME_INTERNAL-8 "ReceivingSlitBox2"
*MEAS_COND_AXIS_NAME_INTERNAL-9 "Filter"
*MEAS_COND_AXIS_NAME_INTERNAL-10 "CounterMonochromator"
*MEAS_COND_AXIS_NAME_INTERNAL-11 "HV"
*MEAS_COND_AXIS_NAME_INTERNAL-12 "PHA"
*MEAS_COND_AXIS_NAME_MAGICNO-0 "268632064.0000000000"
*MEAS_COND_AXIS_NAME_MAGICNO-1 "16842752.0000000000"
*MEAS_COND_AXIS_NAME_MAGICNO-2 "16842752.0000000000"
*MEAS_COND_AXIS_NAME_MAGICNO-3 "20971521.0000000000"
*MEAS_COND_AXIS_NAME_MAGICNO-4 "22020097.0000000000"
*MEAS_COND_AXIS_NAME_MAGICNO-5 "22020097.0000000000"
*MEAS_COND_AXIS_NAME_MAGICNO-6 "23068673.0000000000"
*MEAS_COND_AXIS_NAME_MAGICNO-7 "20971521.0000000000"
*MEAS_COND_AXIS_NAME_MAGICNO-8 "23068673.0000000000"
*MEAS_COND_AXIS_NAME_MAGICNO-9 "20971521.0000000000"
*MEAS_COND_AXIS_NAME_MAGICNO-10 "20971521.0000000000"
*MEAS_COND_AXIS_NAME_MAGICNO-11 "0.0000000000"
*MEAS_COND_AXIS_NAME_MAGICNO-12 "0.0000000000"
*MEAS_COND_AXIS_OFFSET-0 "0.0000000000"
*MEAS_COND_AXIS_OFFSET-1 "-"
*MEAS_COND_AXIS_OFFSET-2 "-"
*MEAS_COND_AXIS_OFFSET-3 "-"
*MEAS_COND_AXIS_OFFSET-4 "-"
*MEAS_COND_AXIS_OFFSET-5 "-"
*MEAS_COND_AXIS_OFFSET-6 "-"
*MEAS_COND_AXIS_OFFSET-7 "-"
*MEAS_COND_AXIS_OFFSET-8 "-"
*MEAS_COND_AXIS_OFFSET-9 "-"
*MEAS_COND_AXIS_OFFSET-10 "-"
*MEAS_COND_AXIS_OFFSET-11 "-"
*MEAS_COND_AXIS_OFFSET-12 "-"
*MEAS_COND_AXIS_POSITION-0 "90.0100000000"
*MEAS_COND_AXIS_POSITION-1 "0.0000000000"
*MEAS_COND_AXIS_POSITION-2 "5.0000000000"
*MEAS_COND_AXIS_POSITION-3 "2.5deg"
*MEAS_COND_AXIS_POSITION-4 "10.0mm"
*MEAS_COND_AXIS_POSITION-5 "1.250deg"
*MEAS_COND_AXIS_POSITION-6 "13.0mm(Open)"
*MEAS_COND_AXIS_POSITION-7 "5.0deg"
*MEAS_COND_AXIS_POSITION-8 "13.0mm"
*MEAS_COND_AXIS_POSITION-9 "None"
*MEAS_COND_AXIS_POSITION-10 "None"
*MEAS_COND_AXIS_POSITION-11 "714.0000000000"
*MEAS_COND_AXIS_POSITION-12 "568.7500000000"
*MEAS_COND_AXIS_UNIT-0 "deg"
*MEAS_COND_AXIS_UNIT-1 ""
*MEAS_COND_AXIS_UNIT-2 ""
*MEAS_COND_AXIS_UNIT-3 ""
*MEAS_COND_AXIS_UNIT-4 ""
*MEAS_COND_AXIS_UNIT-5 ""
*MEAS_COND_AXIS_UNIT-6 ""
*MEAS_COND_AXIS_UNIT-7 ""
*MEAS_COND_AXIS_UNIT-8 ""
*MEAS_COND_AXIS_UNIT-9 ""
*MEAS_COND_AXIS_UNIT-10 ""
*MEAS_COND_AXIS_UNIT-11 "V"
*MEAS_COND_AXIS_UNIT-12 "mV"
*MEAS_COND_CORRECTION_SLIT_COUNTERMONO "None"
*MEAS_COND_CORRECTION_SLIT_DS "1.250deg"
*MEAS_COND_CORRECTION_SLIT_FILTER "None"
*MEAS_COND_CORRECTION_SLIT_IHS "10.0mm"
*MEAS_COND_CORRECTION_SLIT_RS "13.0mm"
*MEAS_COND_CORRECTION_SLIT_SOLLER_INC "2.5deg"
*MEAS_COND_CORRECTION_SLIT_SOLLER_REC "5.0deg"
*MEAS_COND_CORRECTION_SLIT_SS "13.0mm"
*MEAS_COND_COUNTER_CNTLOSS_CORR "0.0000000000"
*MEAS_COND_COUNTER_PHABASE "568.7500000000"
*MEAS_COND_COUNTER_PHAWINDOW "926.2500000000"
*MEAS_COND_COUNTER_PHA_UNIT "mV"
*MEAS_COND_COUNTER_TAUDIFF "0.2500000000"
*MEAS_COND_COUNTER_TAUINT "0.7500000000"
*MEAS_COND_IRRADIATION_MODE "OFF"
*MEAS_COND_IRRADIATION_WIDTH ""
*MEAS_COND_OPT_ATTR " "
*MEAS_COND_OPT_NAME ""
*MEAS_COND_UNSYMMETRIC_MODE "OFF"
*MEAS_COND_XG_CURRENT "15.0000000000"
*MEAS_COND_XG_VOLTAGE "40.0000000000"
*MEAS_COND_XG_WAVE_TYPE "Ka"
*MEAS_DATA_COUNT "4001.0000000000"
*MEAS_SCAN_AXIS_X "Theta/2-Theta"
*MEAS_SCAN_AXIS_X_INTERNAL "TwoThetaTheta"
*MEAS_SCAN_END_TIME "03/07/24 15:59:09"
*MEAS_SCAN_MODE "CONTINUOUS"
*MEAS_SCAN_MONITOR "0"
*MEAS_SCAN_RESOLUTION_X "0.0025"
*MEAS_SCAN_SPEED "2.0000"
*MEAS_SCAN_SPEED_UNIT "deg/min"
*MEAS_SCAN_SPEED_USER "2.0000"
*MEAS_SCAN_START "10.0000000000"
*MEAS_SCAN_START_TIME "03/07/24 15:18:52"
*MEAS_SCAN_STEP "0.0200000000"
*MEAS_SCAN_STOP "90.0000000000"
*MEAS_SCAN_UNIT_X "deg"
*MEAS_SCAN_UNIT_Y "counts"
*SLIT_SYSTEM "0"
*RAS_HEADER_END
*RAS_INT_START
10.0000 869.0000 1.0000
10.0600 962.0000 1.0000
10.1200 912.0000 1.0000
10.1800 870.0000 1.0000
10.2400 858.0000 1.0000
10.3000 780.0000 1.0000
10.3600 855.0000 1.0000
10.4200 823.0000 1.0000
10.4800 899.0000 1.0000
10.5400 830.0000 1.0000
10.6000 859.0000 1.0000
10.6600 922.0000 1.0000
10.7200 806.0000 1.0000
10.7800 845.0000 1.0000
10.8400 843.0000 1.0000
10.9000 895.0000 1.0000
10.9600 826.0000 1.0000
11.0200 853.0000 1.0000
11.0800 850.0000 1.0000
11.1400 846.0000 1.0000
11.2000 805.0000 1.0000
11.2600 782.0000 1.0000
11.3200 859.0000 1.0000
11.3800 756.0000 1.0000
11.4400 803.0000 1.0000
11.5000 797.0000 1.0000
11.5600 817.0000 1.0000
11.6200 824.0000 1.0000
11.6800 881.0000 1.0000
11.7400 831.0000 1.0000
11.8000 832.0000 1.0000
11.8600 818.0000 1.0000
11.9200 772.0000 1.0000
11.9800 773.0000 1.0000
12.0400 784.0000 1.0000
12.1000 773.0000 1.0000
12.1600 804.0000 1.0000
12.2200 755.0000 1.0000
12.2800 798.0000 1.0000
12.3400 725.0000 1.0000
12.4000 760.0000 1.0000
12.4600 773.0000 1.0000
12.5200 793.0000 1.0000
12.5800 703.0000 1.0000
12.6400 805.0000 1.0000
12.7000 683.0000 1.0000
12.7600 789.0000 1.0000
12.8200 731.0000 1.0000
12.8800 718.0000 1.0000
12.9400 711.0000 1.0000
13.0000 799.0000 1.0000
13.0600 703.0000 1.0000
13.1200 722.0000 1.0000
13.1800 734.0000 1.0000
13.2400 755.0000 1.0000
13.3000 726.0000 1.0000
13.3600 724.0000 1.0000
13.4200 710.0000 1.0000
13.4800 707.0000 1.0000
13.5400 703.0000 1.0000
13.6000 718.0000 1.0000
13.6600 690.0000 1.0000
13.7200 704.0000 1.0000
13.7800 731.0000 1.0000
13.8400 700.0000 1.0000
13.9000 672.0000 1.0000
13.9600 696.0000 1.0000
14.0200 718.0000 1.0000
14.0800 698.0000 1.0000
14.1400 672.0000 1.0000
14.2000 616.0000 1.0000
14.2600 694.0000 1.0000
14.3200 673.0000 1.0000
14.3800 711.0000 1.0000
14.4400 668.0000 1.0000
14.5000 705.0000 1.0000
14.5600 699.0000 1.0000
14.6200 621.0000 1.0000
14.6800 701.0000 1.0000
14.7400 655.0000 1.0000
14.8000 669.0000 1.0000
14.8600 637.0000 1.0000
14.9200 629.0000 1.0000
14.9800 639.0000 1.0000
15.0400 640.0000 1.0000
15.1000 655.0000 1.0000
15.1600 677.0000 1.0000
15.2200 658.0000 1.0000
15.2800 642.0000 1.0000
15.3400 618.0000 1.0000
15.4000 633.0000 1.0000
15.4600 609.0000 1.0000
15.5200 654.0000 1.0000
15.5800 563.0000 1.0000
15.6400 607.0000 1.0000
15.7000 587.0000 1.0000
15.7600 617.0000 1.0000
15.8200 635.0000 1.0000
15.8800 656.0000 1.0000
15.9400 646.0000 1.0000
16.0000 618.0000 1.0000
16.0600 561.0000 1.0000
16.1200 595.0000 1.0000
16.1800 605.0000 1.0000
16.2400 602.0000 1.0000
16.3000 588.0000 1.0000
16.3600 578.0000 1.0000
16.4200 633.0000 1.0000
16.4800 620.0000 1.0000
16.5400 590.0000 1.0000
16.6000 620.0000 1.0000
16.6600 617.0000 1.0000
16.7200 543.0000 1.0000
16.7800 623.0000 1.0000
16.8400 554.0000 1.0000
16.9000 559.0000 1.0000
16.9600 549.0000 1.0000
17.0200 543.0000 1.0000
17.0800 589.0000 1.0000
17.1400 556.0000 1.0000
17.2000 581.0000 1.0000
17.2600 590.0000 1.0000
17.3200 538.0000 1.0000
17.3800 525.0000 1.0000
17.4400 576.0000 1.0000
17.5000 602.0000 1.0000
17.5600 591.0000 1.0000
17.6200 536.0000 1.0000
17.6800 557.0000 1.0000
17.7400 545.0000 1.0000
17.8000 542.0000 1.0000
17.8600 545.0000 1.0000
17.9200 600.0000 1.0000
17.9800 540.0000 1.0000
18.0400 568.0000 1.0000
18.1000 507.0000 1.0000
18.1600 567.0000 1.0000
18.2200 550.0000 1.0000
18.2800 571.0000 1.0000
18.3400 550.0000 1.0000
18.4000 533.0000 1.0000
18.4600 565.0000 1.0000
18.5200 540.0000 1.0000
18.5800 533.0000 1.0000
18.6400 601.0000 1.0000
18.7000 594.0000 1.0000
18.7600 604.0000 1.0000
18.8200 561.0000 1.0000
18.8800 539.0000 1.0000
18.9400 540.0000 1.0000
19.0000 565.0000 1.0000
19.0600 542.0000 1.0000
19.1200 535.0000 1.0000
19.1800 500.0000 1.0000
19.2400 555.0000 1.0000
19.3000 517.0000 1.0000
19.3600 530.0000 1.0000
19.4200 503.0000 1.0000
19.4800 523.0000 1.0000
19.5400 521.0000 1.0000
19.6000 542.0000 1.0000
19.6600 553.0000 1.0000
19.7200 518.0000 1.0000
19.7800 507.0000 1.0000
19.8400 491.0000 1.0000
19.9000 506.0000 1.0000
19.9600 503.0000 1.0000
20.0200 549.0000 1.0000
20.0800 526.0000 1.0000
20.1400 520.0000 1.0000
20.2000 530.0000 1.0000
20.2600 553.0000 1.0000
20.3200 532.0000 1.0000
20.3800 536.0000 1.0000
20.4400 535.0000 1.0000
20.5000 485.0000 1.0000
20.5600 530.0000 1.0000
20.6200 497.0000 1.0000
20.6800 496.0000 1.0000
20.7400 511.0000 1.0000
20.8000 507.0000 1.0000
20.8600 529.0000 1.0000
20.9200 521.0000 1.0000
20.9800 521.0000 1.0000
21.0400 530.0000 1.0000
21.1000 508.0000 1.0000
21.1600 561.0000 1.0000
21.2200 558.0000 1.0000
21.2800 564.0000 1.0000
21.3400 546.0000 1.0000
21.4000 529.0000 1.0000
21.4600 560.0000 1.0000
21.5200 521.0000 1.0000
21.5800 530.0000 1.0000
21.6400 529.0000 1.0000
21.7000 537.0000 1.0000
21.7600 551.0000 1.0000
21.8200 533.0000 1.0000
21.8800 551.0000 1.0000
21.9400 500.0000 1.0000
22.0000 560.0000 1.0000
22.0600 568.0000 1.0000
22.1200 516.0000 1.0000
22.1800 497.0000 1.0000
22.2400 518.0000 1.0000
22.3000 548.0000 1.0000
22.3600 523.0000 1.0000
22.4200 490.0000 1.0000
22.4800 535.0000 1.0000
22.5400 514.0000 1.0000
22.6000 555.0000 1.0000
22.6600 541.0000 1.0000
22.7200 509.0000 1.0000
22.7800 541.0000 1.0000
22.8400 491.0000 1.0000
22.9000 514.0000 1.0000
22.9600 535.0000 1.0000
23.0200 540.0000 1.0000
23.0800 563.0000 1.0000
23.1400 532.0000 1.0000
23.2000 488.0000 1.0000
23.2600 534.0000 1.0000
23.3200 484.0000 1.0000
23.3800 555.0000 1.0000
23.4400 507.0000 1.0000
23.5000 526.0000 1.0000
23.5600 510.0000 1.0000
23.6200 501.0000 1.0000
23.6800 543.0000 1.0000
23.7400 591.0000 1.0000
23.8000 563.0000 1.0000
23.8600 531.0000 1.0000
23.9200 524.0000 1.0000
23.9800 521.0000 1.0000
24.0400 537.0000 1.0000
24.1000 539.0000 1.0000
24.1600 548.0000 1.0000
24.2200 539.0000 1.0000
24.2800 549.0000 1.0000
24.3400 513.0000 1.0000
24.4000 555.0000 1.0000
24.4600 519.0000 1.0000
24.5200 551.0000 1.0000
24.5800 574.0000 1.0000
24.6400 524.0000 1.0000
24.7000 547.0000 1.0000
24.7600 566.0000 1.0000
24.8200 512.0000 1.0000
24.8800 510.0000 1.0000
24.9400 531.0000 1.0000
25.0000 540.0000 1.0000
25.0600 530.0000 1.0000
25.1200 525.0000 1.0000
25.1800 578.0000 1.0000
25.2400 544.0000 1.0000
25.3000 557.0000 1.0000
25.3600 539.0000 1.0000
25.4200 534.0000 1.0000
25.4800 524.0000 1.0000
25.5400 514.0000 1.0000
25.6000 543.0000 1.0000
25.6600 549.0000 1.0000
25.7200 532.0000 1.0000
25.7800 537.0000 1.0000
25.8400 532.0000 1.0000
25.9000 541.0000 1.0000
25.9600 528.0000 1.0000
26.0200 521.0000 1.0000
26.0800 535.0000 1.0000
26.1400 542.0000 1.0000
26.2000 533.0000 1.0000
26.2600 515.0000 1.0000
26.3200 536.0000 1.0000
26.3800 552.0000 1.0000
26.4400 519.0000 1.0000
26.5000 510.0000 1.0000
26.5600 516.0000 1.0000
26.6200 547.0000 1.0000
26.6800 572.0000 1.0000
26.7400 545.0000 1.0000
26.8000 526.0000 1.0000
26.8600 561.0000 1.0000
26.9200 531.0000 1.0000
26.9800 561.0000 1.0000
27.0400 566.0000 1.0000
27.1000 560.0000 1.0000
27.1600 569.0000 1.0000
27.2200 527.0000 1.0000
27.2800 533.0000 1.0000
27.3400 559.0000 1.0000
27.4000 545.0000 1.0000
27.4600 578.0000 1.0000
27.5200 524.0000 1.0000
27.5800 550.0000 1.0000
27.6400 573.0000 1.0000
27.7000 530.0000 1.0000
27.7600 492.0000 1.0000
27.8200 505.0000 1.0000
27.8800 508.0000 1.0000
27.9400 549.0000 1.0000
28.0000 561.0000 1.0000
28.0600 525.0000 1.0000
28.1200 508.0000 1.0000
28.1800 539.0000 1.0000
28.2400 547.0000 1.0000
28.3000 547.0000 1.0000
28.3600 536.0000 1.0000
28.4200 519.0000 1.0000
28.4800 535.0000 1.0000
28.5400 544.0000 1.0000
28.6000 510.0000 1.0000
28.6600 522.0000 1.0000
28.7200 523.0000 1.0000
28.7800 550.0000 1.0000
28.8400 554.0000 1.0000
28.9000 548.0000 1.0000
28.9600 528.0000 1.0000
29.0200 547.0000 1.0000
29.0800 528.0000 1.0000
29.1400 482.0000 1.0000
29.2000 520.0000 1.0000
29.2600 519.0000 1.0000
29.3200 555.0000 1.0000
29.3800 527.0000 1.0000
29.4400 513.0000 1.0000
29.5000 544.0000 1.0000
29.5600 541.0000 1.0000
29.6200 543.0000 1.0000
29.6800 560.0000 1.0000
29.7400 537.0000 1.0000
29.8000 579.0000 1.0000
29.8600 581.0000 1.0000
29.9200 547.0000 1.0000
29.9800 516.0000 1.0000
30.0400 516.0000 1.0000
30.1000 534.0000 1.0000
30.1600 531.0000 1.0000
30.2200 562.0000 1.0000
30.2800 607.0000 1.0000
30.3400 585.0000 1.0000
30.4000 579.0000 1.0000
30.4600 692.0000 1.0000
30.5200 777.0000 1.0000
30.5800 637.0000 1.0000
30.6400 593.0000 1.0000
30.7000 564.0000 1.0000
30.7600 563.0000 1.0000
30.8200 532.0000 1.0000
30.8800 517.0000 1.0000
30.9400 538.0000 1.0000
31.0000 575.0000 1.0000
31.0600 524.0000 1.0000
31.1200 574.0000 1.0000
31.1800 560.0000 1.0000
31.2400 532.0000 1.0000
31.3000 528.0000 1.0000
31.3600 524.0000 1.0000
31.4200 539.0000 1.0000
31.4800 530.0000 1.0000
31.5400 538.0000 1.0000
31.6000 521.0000 1.0000
31.6600 512.0000 1.0000
31.7200 492.0000 1.0000
31.7800 498.0000 1.0000
31.8400 548.0000 1.0000
31.9000 517.0000 1.0000
31.9600 564.0000 1.0000
32.0200 577.0000 1.0000
32.0800 554.0000 1.0000
32.1400 555.0000 1.0000
32.2000 538.0000 1.0000
32.2600 531.0000 1.0000
32.3200 568.0000 1.0000
32.3800 531.0000 1.0000
32.4400 544.0000 1.0000
32.5000 535.0000 1.0000
32.5600 600.0000 1.0000
32.6200 525.0000 1.0000
32.6800 544.0000 1.0000
32.7400 572.0000 1.0000
32.8000 542.0000 1.0000
32.8600 531.0000 1.0000
32.9200 553.0000 1.0000
32.9800 537.0000 1.0000
33.0400 525.0000 1.0000
33.1000 560.0000 1.0000
33.1600 548.0000 1.0000
33.2200 521.0000 1.0000
33.2800 526.0000 1.0000
33.3400 546.0000 1.0000
33.4000 551.0000 1.0000
33.4600 522.0000 1.0000
33.5200 537.0000 1.0000
33.5800 525.0000 1.0000
33.6400 523.0000 1.0000
33.7000 537.0000 1.0000
33.7600 537.0000 1.0000
33.8200 562.0000 1.0000
33.8800 544.0000 1.0000
33.9400 535.0000 1.0000
34.0000 569.0000 1.0000
34.0600 525.0000 1.0000
34.1200 501.0000 1.0000
34.1800 555.0000 1.0000
34.2400 561.0000 1.0000
34.3000 548.0000 1.0000
34.3600 524.0000 1.0000
34.4200 519.0000 1.0000
34.4800 510.0000 1.0000
34.5400 542.0000 1.0000
34.6000 527.0000 1.0000
34.6600 595.0000 1.0000
34.7200 533.0000 1.0000
34.7800 551.0000 1.0000
34.8400 568.0000 1.0000
34.9000 555.0000 1.0000
34.9600 593.0000 1.0000
35.0200 581.0000 1.0000
35.0800 518.0000 1.0000
35.1400 538.0000 1.0000
35.2000 549.0000 1.0000
35.2600 552.0000 1.0000
35.3200 530.0000 1.0000
35.3800 582.0000 1.0000
35.4400 570.0000 1.0000
35.5000 592.0000 1.0000
35.5600 646.0000 1.0000
35.6200 738.0000 1.0000
35.6800 815.0000 1.0000
35.7400 1041.0000 1.0000
35.8000 1145.0000 1.0000
35.8600 1164.0000 1.0000
35.9200 1017.0000 1.0000
35.9800 845.0000 1.0000
36.0400 747.0000 1.0000
36.1000 623.0000 1.0000
36.1600 607.0000 1.0000
36.2200 624.0000 1.0000
36.2800 617.0000 1.0000
36.3400 557.0000 1.0000
36.4000 549.0000 1.0000
36.4600 557.0000 1.0000
36.5200 545.0000 1.0000
36.5800 557.0000 1.0000
36.6400 578.0000 1.0000
36.7000 539.0000 1.0000
36.7600 565.0000 1.0000
36.8200 559.0000 1.0000
36.8800 539.0000 1.0000
36.9400 576.0000 1.0000
37.0000 586.0000 1.0000
37.0600 531.0000 1.0000
37.1200 562.0000 1.0000
37.1800 514.0000 1.0000
37.2400 557.0000 1.0000
37.3000 557.0000 1.0000
37.3600 545.0000 1.0000
37.4200 564.0000 1.0000
37.4800 533.0000 1.0000
37.5400 553.0000 1.0000
37.6000 543.0000 1.0000
37.6600 583.0000 1.0000
37.7200 568.0000 1.0000
37.7800 507.0000 1.0000
37.8400 538.0000 1.0000
37.9000 532.0000 1.0000
37.9600 538.0000 1.0000
38.0200 539.0000 1.0000
38.0800 529.0000 1.0000
38.1400 587.0000 1.0000
38.2000 562.0000 1.0000
38.2600 538.0000 1.0000
38.3200 563.0000 1.0000
38.3800 557.0000 1.0000
38.4400 587.0000 1.0000
38.5000 555.0000 1.0000
38.5600 540.0000 1.0000
38.6200 518.0000 1.0000
38.6800 518.0000 1.0000
38.7400 526.0000 1.0000
38.8000 563.0000 1.0000
38.8600 542.0000 1.0000
38.9200 520.0000 1.0000
38.9800 551.0000 1.0000
39.0400 531.0000 1.0000
39.1000 542.0000 1.0000
39.1600 553.0000 1.0000
39.2200 502.0000 1.0000
39.2800 543.0000 1.0000
39.3400 539.0000 1.0000
39.4000 566.0000 1.0000
39.4600 542.0000 1.0000
39.5200 588.0000 1.0000
39.5800 541.0000 1.0000
39.6400 552.0000 1.0000
39.7000 544.0000 1.0000
39.7600 524.0000 1.0000
39.8200 512.0000 1.0000
39.8800 550.0000 1.0000
39.9400 524.0000 1.0000
40.0000 537.0000 1.0000
40.0600 540.0000 1.0000
40.1200 561.0000 1.0000
40.1800 559.0000 1.0000
40.2400 526.0000 1.0000
40.3000 541.0000 1.0000
40.3600 531.0000 1.0000
40.4200 563.0000 1.0000
40.4800 559.0000 1.0000
40.5400 550.0000 1.0000
40.6000 525.0000 1.0000
40.6600 553.0000 1.0000
40.7200 519.0000 1.0000
40.7800 533.0000 1.0000
40.8400 531.0000 1.0000
40.9000 548.0000 1.0000
40.9600 526.0000 1.0000
41.0200 526.0000 1.0000
41.0800 546.0000 1.0000
41.1400 569.0000 1.0000
41.2000 593.0000 1.0000
41.2600 573.0000 1.0000
41.3200 521.0000 1.0000
41.3800 542.0000 1.0000
41.4400 530.0000 1.0000
41.5000 513.0000 1.0000
41.5600 578.0000 1.0000
41.6200 503.0000 1.0000
41.6800 551.0000 1.0000
41.7400 515.0000 1.0000
41.8000 520.0000 1.0000
41.8600 560.0000 1.0000
41.9200 567.0000 1.0000
41.9800 542.0000 1.0000
42.0400 531.0000 1.0000
42.1000 565.0000 1.0000
42.1600 548.0000 1.0000
42.2200 563.0000 1.0000
42.2800 568.0000 1.0000
42.3400 542.0000 1.0000
42.4000 533.0000 1.0000
42.4600 581.0000 1.0000
42.5200 532.0000 1.0000
42.5800 556.0000 1.0000
42.6400 571.0000 1.0000
42.7000 562.0000 1.0000
42.7600 558.0000 1.0000
42.8200 606.0000 1.0000
42.8800 513.0000 1.0000
42.9400 533.0000 1.0000
43.0000 543.0000 1.0000
43.0600 570.0000 1.0000
43.1200 576.0000 1.0000
43.1800 564.0000 1.0000
43.2400 609.0000 1.0000
43.3000 642.0000 1.0000
43.3600 627.0000 1.0000
43.4200 614.0000 1.0000
43.4800 665.0000 1.0000
43.5400 609.0000 1.0000
43.6000 625.0000 1.0000
43.6600 595.0000 1.0000
43.7200 568.0000 1.0000
43.7800 573.0000 1.0000
43.8400 555.0000 1.0000
43.9000 531.0000 1.0000
43.9600 564.0000 1.0000
44.0200 598.0000 1.0000
44.0800 574.0000 1.0000
44.1400 509.0000 1.0000
44.2000 534.0000 1.0000
44.2600 591.0000 1.0000
44.3200 541.0000 1.0000
44.3800 560.0000 1.0000
44.4400 570.0000 1.0000
44.5000 534.0000 1.0000
44.5600 551.0000 1.0000
44.6200 547.0000 1.0000
44.6800 538.0000 1.0000
44.7400 509.0000 1.0000
44.8000 565.0000 1.0000
44.8600 529.0000 1.0000
44.9200 515.0000 1.0000
44.9800 574.0000 1.0000
45.0400 559.0000 1.0000
45.1000 518.0000 1.0000
45.1600 504.0000 1.0000
45.2200 551.0000 1.0000
45.2800 574.0000 1.0000
45.3400 527.0000 1.0000
45.4000 551.0000 1.0000
45.4600 570.0000 1.0000
45.5200 544.0000 1.0000
45.5800 582.0000 1.0000
45.6400 536.0000 1.0000
45.7000 557.0000 1.0000
45.7600 522.0000 1.0000
45.8200 539.0000 1.0000
45.8800 527.0000 1.0000
45.9400 562.0000 1.0000
46.0000 521.0000 1.0000
46.0600 567.0000 1.0000
46.1200 519.0000 1.0000
46.1800 557.0000 1.0000
46.2400 560.0000 1.0000
46.3000 519.0000 1.0000
46.3600 533.0000 1.0000
46.4200 497.0000 1.0000
46.4800 531.0000 1.0000
46.5400 495.0000 1.0000
46.6000 564.0000 1.0000
46.6600 542.0000 1.0000
46.7200 555.0000 1.0000
46.7800 548.0000 1.0000
46.8400 577.0000 1.0000
46.9000 547.0000 1.0000
46.9600 533.0000 1.0000
47.0200 581.0000 1.0000
47.0800 544.0000 1.0000
47.1400 542.0000 1.0000
47.2000 550.0000 1.0000
47.2600 564.0000 1.0000
47.3200 563.0000 1.0000
47.3800 558.0000 1.0000
47.4400 569.0000 1.0000
47.5000 578.0000 1.0000
47.5600 622.0000 1.0000
47.6200 514.0000 1.0000
47.6800 546.0000 1.0000
47.7400 549.0000 1.0000
47.8000 538.0000 1.0000
47.8600 549.0000 1.0000
47.9200 516.0000 1.0000
47.9800 548.0000 1.0000
48.0400 561.0000 1.0000
48.1000 543.0000 1.0000
48.1600 580.0000 1.0000
48.2200 540.0000 1.0000
48.2800 547.0000 1.0000
48.3400 524.0000 1.0000
48.4000 580.0000 1.0000
48.4600 542.0000 1.0000
48.5200 539.0000 1.0000
48.5800 526.0000 1.0000
48.6400 553.0000 1.0000
48.7000 575.0000 1.0000
48.7600 559.0000 1.0000
48.8200 545.0000 1.0000
48.8800 537.0000 1.0000
48.9400 565.0000 1.0000
49.0000 547.0000 1.0000
49.0600 534.0000 1.0000
49.1200 574.0000 1.0000
49.1800 534.0000 1.0000
49.2400 525.0000 1.0000
49.3000 537.0000 1.0000
49.3600 513.0000 1.0000
49.4200 523.0000 1.0000
49.4800 616.0000 1.0000
49.5400 531.0000 1.0000
49.6000 561.0000 1.0000
49.6600 541.0000 1.0000
49.7200 520.0000 1.0000
49.7800 555.0000 1.0000
49.8400 551.0000 1.0000
49.9000 574.0000 1.0000
49.9600 552.0000 1.0000
50.0200 527.0000 1.0000
50.0800 530.0000 1.0000
50.1400 569.0000 1.0000
50.2000 598.0000 1.0000
50.2600 569.0000 1.0000
50.3200 550.0000 1.0000
50.3800 534.0000 1.0000
50.4400 550.0000 1.0000
50.5000 533.0000 1.0000
50.5600 535.0000 1.0000
50.6200 549.0000 1.0000
50.6800 521.0000 1.0000
50.7400 555.0000 1.0000
50.8000 548.0000 1.0000
50.8600 561.0000 1.0000
50.9200 568.0000 1.0000
50.9800 535.0000 1.0000
51.0400 537.0000 1.0000
51.1000 527.0000 1.0000
51.1600 557.0000 1.0000
51.2200 544.0000 1.0000
51.2800 557.0000 1.0000
51.3400 585.0000 1.0000
51.4000 577.0000 1.0000
51.4600 564.0000 1.0000
51.5200 535.0000 1.0000
51.5800 554.0000 1.0000
51.6400 546.0000 1.0000
51.7000 559.0000 1.0000
51.7600 553.0000 1.0000
51.8200 553.0000 1.0000
51.8800 568.0000 1.0000
51.9400 595.0000 1.0000
52.0000 548.0000 1.0000
52.0600 551.0000 1.0000
52.1200 568.0000 1.0000
52.1800 581.0000 1.0000
52.2400 525.0000 1.0000
52.3000 551.0000 1.0000
52.3600 547.0000 1.0000
52.4200 561.0000 1.0000
52.4800 521.0000 1.0000
52.5400 548.0000 1.0000
52.6000 549.0000 1.0000
52.6600 568.0000 1.0000
52.7200 557.0000 1.0000
52.7800 523.0000 1.0000
52.8400 565.0000 1.0000
52.9000 551.0000 1.0000
52.9600 555.0000 1.0000
53.0200 566.0000 1.0000
53.0800 499.0000 1.0000
53.1400 530.0000 1.0000
53.2000 548.0000 1.0000
53.2600 526.0000 1.0000
53.3200 520.0000 1.0000
53.3800 534.0000 1.0000
53.4400 568.0000 1.0000
53.5000 540.0000 1.0000
53.5600 576.0000 1.0000
53.6200 571.0000 1.0000
53.6800 554.0000 1.0000
53.7400 622.0000 1.0000
53.8000 597.0000 1.0000
53.8600 560.0000 1.0000
53.9200 556.0000 1.0000
53.9800 617.0000 1.0000
54.0400 580.0000 1.0000
54.1000 521.0000 1.0000
54.1600 544.0000 1.0000
54.2200 574.0000 1.0000
54.2800 546.0000 1.0000
54.3400 550.0000 1.0000
54.4000 530.0000 1.0000
54.4600 541.0000 1.0000
54.5200 510.0000 1.0000
54.5800 563.0000 1.0000
54.6400 556.0000 1.0000
54.7000 574.0000 1.0000
54.7600 512.0000 1.0000
54.8200 536.0000 1.0000
54.8800 536.0000 1.0000
54.9400 548.0000 1.0000
55.0000 565.0000 1.0000
55.0600 573.0000 1.0000
55.1200 560.0000 1.0000
55.1800 514.0000 1.0000
55.2400 561.0000 1.0000
55.3000 571.0000 1.0000
55.3600 544.0000 1.0000
55.4200 522.0000 1.0000
55.4800 586.0000 1.0000
55.5400 512.0000 1.0000
55.6000 562.0000 1.0000
55.6600 529.0000 1.0000
55.7200 534.0000 1.0000
55.7800 559.0000 1.0000
55.8400 511.0000 1.0000
55.9000 586.0000 1.0000
55.9600 583.0000 1.0000
56.0200 591.0000 1.0000
56.0800 537.0000 1.0000
56.1400 552.0000 1.0000
56.2000 533.0000 1.0000
56.2600 577.0000 1.0000
56.3200 588.0000 1.0000
56.3800 575.0000 1.0000
56.4400 587.0000 1.0000
56.5000 543.0000 1.0000
56.5600 544.0000 1.0000
56.6200 547.0000 1.0000
56.6800 536.0000 1.0000
56.7400 537.0000 1.0000
56.8000 554.0000 1.0000
56.8600 545.0000 1.0000
56.9200 593.0000 1.0000
56.9800 568.0000 1.0000
57.0400 624.0000 1.0000
57.1000 605.0000 1.0000
57.1600 638.0000 1.0000
57.2200 706.0000 1.0000
57.2800 706.0000 1.0000
57.3400 681.0000 1.0000
57.4000 701.0000 1.0000
57.4600 655.0000 1.0000
57.5200 653.0000 1.0000
57.5800 578.0000 1.0000
57.6400 565.0000 1.0000
57.7000 576.0000 1.0000
57.7600 557.0000 1.0000
57.8200 571.0000 1.0000
57.8800 572.0000 1.0000
57.9400 558.0000 1.0000
58.0000 550.0000 1.0000
58.0600 564.0000 1.0000
58.1200 527.0000 1.0000
58.1800 518.0000 1.0000
58.2400 533.0000 1.0000
58.3000 521.0000 1.0000
58.3600 504.0000 1.0000
58.4200 556.0000 1.0000
58.4800 574.0000 1.0000
58.5400 524.0000 1.0000
58.6000 605.0000 1.0000
58.6600 569.0000 1.0000
58.7200 555.0000 1.0000
58.7800 556.0000 1.0000
58.8400 557.0000 1.0000
58.9000 561.0000 1.0000
58.9600 536.0000 1.0000
59.0200 560.0000 1.0000
59.0800 548.0000 1.0000
59.1400 558.0000 1.0000
59.2000 491.0000 1.0000
59.2600 539.0000 1.0000
59.3200 558.0000 1.0000
59.3800 541.0000 1.0000
59.4400 528.0000 1.0000
59.5000 571.0000 1.0000
59.5600 558.0000 1.0000
59.6200 571.0000 1.0000
59.6800 537.0000 1.0000
59.7400 575.0000 1.0000
59.8000 536.0000 1.0000
59.8600 507.0000 1.0000
59.9200 543.0000 1.0000
59.9800 565.0000 1.0000
60.0400 569.0000 1.0000
60.1000 600.0000 1.0000
60.1600 531.0000 1.0000
60.2200 586.0000 1.0000
60.2800 588.0000 1.0000
60.3400 492.0000 1.0000
60.4000 530.0000 1.0000
60.4600 564.0000 1.0000
60.5200 502.0000 1.0000
60.5800 531.0000 1.0000
60.6400 565.0000 1.0000
60.7000 531.0000 1.0000
60.7600 512.0000 1.0000
60.8200 507.0000 1.0000
60.8800 561.0000 1.0000
60.9400 578.0000 1.0000
61.0000 544.0000 1.0000
61.0600 550.0000 1.0000
61.1200 567.0000 1.0000
61.1800 540.0000 1.0000
61.2400 554.0000 1.0000
61.3000 568.0000 1.0000
61.3600 590.0000 1.0000
61.4200 529.0000 1.0000
61.4800 599.0000 1.0000
61.5400 529.0000 1.0000
61.6000 586.0000 1.0000
61.6600 557.0000 1.0000
61.7200 519.0000 1.0000
61.7800 557.0000 1.0000
61.8400 563.0000 1.0000
61.9000 523.0000 1.0000
61.9600 535.0000 1.0000
62.0200 545.0000 1.0000
62.0800 575.0000 1.0000
62.1400 574.0000 1.0000
62.2000 599.0000 1.0000
62.2600 550.0000 1.0000
62.3200 583.0000 1.0000
62.3800 548.0000 1.0000
62.4400 588.0000 1.0000
62.5000 568.0000 1.0000
62.5600 607.0000 1.0000
62.6200 608.0000 1.0000
62.6800 614.0000 1.0000
62.7400 640.0000 1.0000
62.8000 715.0000 1.0000
62.8600 699.0000 1.0000
62.9200 723.0000 1.0000
62.9800 687.0000 1.0000
63.0400 679.0000 1.0000
63.1000 642.0000 1.0000
63.1600 673.0000 1.0000
63.2200 574.0000 1.0000
63.2800 577.0000 1.0000
63.3400 616.0000 1.0000
63.4000 549.0000 1.0000
63.4600 566.0000 1.0000
63.5200 573.0000 1.0000
63.5800 530.0000 1.0000
63.6400 553.0000 1.0000
63.7000 567.0000 1.0000
63.7600 511.0000 1.0000
63.8200 586.0000 1.0000
63.8800 561.0000 1.0000
63.9400 522.0000 1.0000
64.0000 586.0000 1.0000
64.0600 558.0000 1.0000
64.1200 558.0000 1.0000
64.1800 579.0000 1.0000
64.2400 532.0000 1.0000
64.3000 547.0000 1.0000
64.3600 539.0000 1.0000
64.4200 562.0000 1.0000
64.4800 564.0000 1.0000
64.5400 503.0000 1.0000
64.6000 556.0000 1.0000
64.6600 558.0000 1.0000
64.7200 573.0000 1.0000
64.7800 533.0000 1.0000
64.8400 562.0000 1.0000
64.9000 566.0000 1.0000
64.9600 512.0000 1.0000
65.0200 528.0000 1.0000
65.0800 559.0000 1.0000
65.1400 528.0000 1.0000
65.2000 553.0000 1.0000
65.2600 591.0000 1.0000
65.3200 535.0000 1.0000
65.3800 563.0000 1.0000
65.4400 532.0000 1.0000
65.5000 556.0000 1.0000
65.5600 547.0000 1.0000
65.6200 514.0000 1.0000
65.6800 568.0000 1.0000
65.7400 564.0000 1.0000
65.8000 538.0000 1.0000
65.8600 561.0000 1.0000
65.9200 567.0000 1.0000
65.9800 582.0000 1.0000
66.0400 558.0000 1.0000
66.1000 537.0000 1.0000
66.1600 570.0000 1.0000
66.2200 542.0000 1.0000
66.2800 542.0000 1.0000
66.3400 571.0000 1.0000
66.4000 547.0000 1.0000
66.4600 522.0000 1.0000
66.5200 586.0000 1.0000
66.5800 591.0000 1.0000
66.6400 533.0000 1.0000
66.7000 583.0000 1.0000
66.7600 532.0000 1.0000
66.8200 546.0000 1.0000
66.8800 584.0000 1.0000
66.9400 568.0000 1.0000
67.0000 574.0000 1.0000
67.0600 630.0000 1.0000
67.1200 561.0000 1.0000
67.1800 561.0000 1.0000
67.2400 569.0000 1.0000
67.3000 615.0000 1.0000
67.3600 556.0000 1.0000
67.4200 534.0000 1.0000
67.4800 555.0000 1.0000
67.5400 567.0000 1.0000
67.6000 563.0000 1.0000
67.6600 523.0000 1.0000
67.7200 560.0000 1.0000
67.7800 544.0000 1.0000
67.8400 522.0000 1.0000
67.9000 594.0000 1.0000
67.9600 562.0000 1.0000
68.0200 518.0000 1.0000
68.0800 564.0000 1.0000
68.1400 547.0000 1.0000
68.2000 537.0000 1.0000
68.2600 555.0000 1.0000
68.3200 541.0000 1.0000
68.3800 551.0000 1.0000
68.4400 546.0000 1.0000
68.5000 539.0000 1.0000
68.5600 531.0000 1.0000
68.6200 564.0000 1.0000
68.6800 546.0000 1.0000
68.7400 533.0000 1.0000
68.8000 538.0000 1.0000
68.8600 571.0000 1.0000
68.9200 542.0000 1.0000
68.9800 557.0000 1.0000
69.0400 535.0000 1.0000
69.1000 523.0000 1.0000
69.1600 543.0000 1.0000
69.2200 543.0000 1.0000
69.2800 539.0000 1.0000
69.3400 552.0000 1.0000
69.4000 568.0000 1.0000
69.4600 525.0000 1.0000
69.5200 577.0000 1.0000
69.5800 531.0000 1.0000
69.6400 559.0000 1.0000
69.7000 563.0000 1.0000
69.7600 547.0000 1.0000
69.8200 565.0000 1.0000
69.8800 535.0000 1.0000
69.9400 533.0000 1.0000
70.0000 567.0000 1.0000
70.0600 533.0000 1.0000
70.1200 577.0000 1.0000
70.1800 539.0000 1.0000
70.2400 540.0000 1.0000
70.3000 500.0000 1.0000
70.3600 547.0000 1.0000
70.4200 491.0000 1.0000
70.4800 531.0000 1.0000
70.5400 552.0000 1.0000
70.6000 550.0000 1.0000
70.6600 569.0000 1.0000
70.7200 538.0000 1.0000
70.7800 583.0000 1.0000
70.8400 531.0000 1.0000
70.9000 539.0000 1.0000
70.9600 549.0000 1.0000
71.0200 534.0000 1.0000
71.0800 565.0000 1.0000
71.1400 571.0000 1.0000
71.2000 552.0000 1.0000
71.2600 546.0000 1.0000
71.3200 637.0000 1.0000
71.3800 570.0000 1.0000
71.4400 562.0000 1.0000
71.5000 601.0000 1.0000
71.5600 535.0000 1.0000
71.6200 551.0000 1.0000
71.6800 563.0000 1.0000
71.7400 559.0000 1.0000
71.8000 523.0000 1.0000
71.8600 503.0000 1.0000
71.9200 561.0000 1.0000
71.9800 568.0000 1.0000
72.0400 528.0000 1.0000
72.1000 528.0000 1.0000
72.1600 580.0000 1.0000
72.2200 563.0000 1.0000
72.2800 541.0000 1.0000
72.3400 560.0000 1.0000
72.4000 563.0000 1.0000
72.4600 540.0000 1.0000
72.5200 525.0000 1.0000
72.5800 545.0000 1.0000
72.6400 541.0000 1.0000
72.7000 580.0000 1.0000
72.7600 521.0000 1.0000
72.8200 557.0000 1.0000
72.8800 562.0000 1.0000
72.9400 518.0000 1.0000
73.0000 607.0000 1.0000
73.0600 581.0000 1.0000
73.1200 539.0000 1.0000
73.1800 511.0000 1.0000
73.2400 572.0000 1.0000
73.3000 551.0000 1.0000
73.3600 566.0000 1.0000
73.4200 576.0000 1.0000
73.4800 522.0000 1.0000
73.5400 542.0000 1.0000
73.6000 549.0000 1.0000
73.6600 569.0000 1.0000
73.7200 550.0000 1.0000
73.7800 524.0000 1.0000
73.8400 545.0000 1.0000
73.9000 534.0000 1.0000
73.9600 566.0000 1.0000
74.0200 554.0000 1.0000
74.0800 533.0000 1.0000
74.1400 549.0000 1.0000
74.2000 542.0000 1.0000
74.2600 578.0000 1.0000
74.3200 572.0000 1.0000
74.3800 567.0000 1.0000
74.4400 570.0000 1.0000
74.5000 559.0000 1.0000
74.5600 557.0000 1.0000
74.6200 562.0000 1.0000
74.6800 554.0000 1.0000
74.7400 544.0000 1.0000
74.8000 568.0000 1.0000
74.8600 558.0000 1.0000
74.9200 591.0000 1.0000
74.9800 572.0000 1.0000
75.0400 607.0000 1.0000
75.1000 554.0000 1.0000
75.1600 568.0000 1.0000
75.2200 604.0000 1.0000
75.2800 570.0000 1.0000
75.3400 573.0000 1.0000
75.4000 524.0000 1.0000
75.4600 580.0000 1.0000
75.5200 526.0000 1.0000
75.5800 531.0000 1.0000
75.6400 530.0000 1.0000
75.7000 525.0000 1.0000
75.7600 566.0000 1.0000
75.8200 556.0000 1.0000
75.8800 519.0000 1.0000
75.9400 526.0000 1.0000
76.0000 577.0000 1.0000
76.0600 566.0000 1.0000
76.1200 532.0000 1.0000
76.1800 534.0000 1.0000
76.2400 595.0000 1.0000
76.3000 602.0000 1.0000
76.3600 568.0000 1.0000
76.4200 572.0000 1.0000
76.4800 555.0000 1.0000
76.5400 506.0000 1.0000
76.6000 587.0000 1.0000
76.6600 596.0000 1.0000
76.7200 532.0000 1.0000
76.7800 512.0000 1.0000
76.8400 556.0000 1.0000
76.9000 572.0000 1.0000
76.9600 517.0000 1.0000
77.0200 590.0000 1.0000
77.0800 619.0000 1.0000
77.1400 541.0000 1.0000
77.2000 532.0000 1.0000
77.2600 593.0000 1.0000
77.3200 546.0000 1.0000
77.3800 539.0000 1.0000
77.4400 529.0000 1.0000
77.5000 595.0000 1.0000
77.5600 563.0000 1.0000
77.6200 545.0000 1.0000
77.6800 549.0000 1.0000
77.7400 546.0000 1.0000
77.8000 571.0000 1.0000
77.8600 513.0000 1.0000
77.9200 544.0000 1.0000
77.9800 528.0000 1.0000
78.0400 544.0000 1.0000
78.1000 544.0000 1.0000
78.1600 533.0000 1.0000
78.2200 592.0000 1.0000
78.2800 557.0000 1.0000
78.3400 542.0000 1.0000
78.4000 582.0000 1.0000
78.4600 569.0000 1.0000
78.5200 547.0000 1.0000
78.5800 579.0000 1.0000
78.6400 578.0000 1.0000
78.7000 558.0000 1.0000
78.7600 569.0000 1.0000
78.8200 531.0000 1.0000
78.8800 520.0000 1.0000
78.9400 536.0000 1.0000
79.0000 555.0000 1.0000
79.0600 556.0000 1.0000
79.1200 571.0000 1.0000
79.1800 569.0000 1.0000
79.2400 539.0000 1.0000
79.3000 550.0000 1.0000
79.3600 579.0000 1.0000
79.4200 494.0000 1.0000
79.4800 540.0000 1.0000
79.5400 529.0000 1.0000
79.6000 539.0000 1.0000
79.6600 500.0000 1.0000
79.7200 565.0000 1.0000
79.7800 575.0000 1.0000
79.8400 560.0000 1.0000
79.9000 539.0000 1.0000
79.9600 533.0000 1.0000
80.0200 539.0000 1.0000
80.0800 584.0000 1.0000
80.1400 566.0000 1.0000
80.2000 555.0000 1.0000
80.2600 556.0000 1.0000
80.3200 495.0000 1.0000
80.3800 543.0000 1.0000
80.4400 533.0000 1.0000
80.5000 569.0000 1.0000
80.5600 545.0000 1.0000
80.6200 527.0000 1.0000
80.6800 547.0000 1.0000
80.7400 561.0000 1.0000
80.8000 571.0000 1.0000
80.8600 479.0000 1.0000
80.9200 515.0000 1.0000
80.9800 572.0000 1.0000
81.0400 537.0000 1.0000
81.1000 547.0000 1.0000
81.1600 543.0000 1.0000
81.2200 540.0000 1.0000
81.2800 577.0000 1.0000
81.3400 527.0000 1.0000
81.4000 542.0000 1.0000
81.4600 558.0000 1.0000
81.5200 595.0000 1.0000
81.5800 580.0000 1.0000
81.6400 558.0000 1.0000
81.7000 536.0000 1.0000
81.7600 552.0000 1.0000
81.8200 555.0000 1.0000
81.8800 547.0000 1.0000
81.9400 554.0000 1.0000
82.0000 549.0000 1.0000
82.0600 522.0000 1.0000
82.1200 560.0000 1.0000
82.1800 575.0000 1.0000
82.2400 575.0000 1.0000
82.3000 554.0000 1.0000
82.3600 595.0000 1.0000
82.4200 569.0000 1.0000
82.4800 553.0000 1.0000
82.5400 554.0000 1.0000
82.6000 567.0000 1.0000
82.6600 605.0000 1.0000
82.7200 614.0000 1.0000
82.7800 554.0000 1.0000
82.8400 508.0000 1.0000
82.9000 589.0000 1.0000
82.9600 547.0000 1.0000
83.0200 549.0000 1.0000
83.0800 569.0000 1.0000
83.1400 539.0000 1.0000
83.2000 528.0000 1.0000
83.2600 556.0000 1.0000
83.3200 520.0000 1.0000
83.3800 557.0000 1.0000
83.4400 585.0000 1.0000
83.5000 575.0000 1.0000
83.5600 554.0000 1.0000
83.6200 518.0000 1.0000
83.6800 579.0000 1.0000
83.7400 548.0000 1.0000
83.8000 601.0000 1.0000
83.8600 641.0000 1.0000
83.9200 550.0000 1.0000
83.9800 532.0000 1.0000
84.0400 547.0000 1.0000
84.1000 591.0000 1.0000
84.1600 554.0000 1.0000
84.2200 559.0000 1.0000
84.2800 496.0000 1.0000
84.3400 535.0000 1.0000
84.4000 488.0000 1.0000
84.4600 530.0000 1.0000
84.5200 535.0000 1.0000
84.5800 538.0000 1.0000
84.6400 548.0000 1.0000
84.7000 531.0000 1.0000
84.7600 578.0000 1.0000
84.8200 541.0000 1.0000
84.8800 532.0000 1.0000
84.9400 564.0000 1.0000
85.0000 558.0000 1.0000
85.0600 573.0000 1.0000
85.1200 573.0000 1.0000
85.1800 550.0000 1.0000
85.2400 560.0000 1.0000
85.3000 550.0000 1.0000
85.3600 575.0000 1.0000
85.4200 535.0000 1.0000
85.4800 558.0000 1.0000
85.5400 580.0000 1.0000
85.6000 564.0000 1.0000
85.6600 542.0000 1.0000
85.7200 544.0000 1.0000
85.7800 513.0000 1.0000
85.8400 526.0000 1.0000
85.9000 541.0000 1.0000
85.9600 603.0000 1.0000
86.0200 559.0000 1.0000
86.0800 589.0000 1.0000
86.1400 539.0000 1.0000
86.2000 545.0000 1.0000
86.2600 605.0000 1.0000
86.3200 549.0000 1.0000
86.3800 510.0000 1.0000
86.4400 557.0000 1.0000
86.5000 571.0000 1.0000
86.5600 599.0000 1.0000
86.6200 561.0000 1.0000
86.6800 539.0000 1.0000
86.7400 605.0000 1.0000
86.8000 538.0000 1.0000
86.8600 532.0000 1.0000
86.9200 551.0000 1.0000
86.9800 553.0000 1.0000
87.0400 565.0000 1.0000
87.1000 588.0000 1.0000
87.1600 559.0000 1.0000
87.2200 550.0000 1.0000
87.2800 485.0000 1.0000
87.3400 531.0000 1.0000
87.4000 533.0000 1.0000
87.4600 548.0000 1.0000
87.5200 521.0000 1.0000
87.5800 559.0000 1.0000
87.6400 571.0000 1.0000
87.7000 548.0000 1.0000
87.7600 599.0000 1.0000
87.8200 508.0000 1.0000
87.8800 580.0000 1.0000
87.9400 552.0000 1.0000
88.0000 565.0000 1.0000
88.0600 546.0000 1.0000
88.1200 538.0000 1.0000
88.1800 550.0000 1.0000
88.2400 584.0000 1.0000
88.3000 549.0000 1.0000
88.3600 585.0000 1.0000
88.4200 560.0000 1.0000
88.4800 553.0000 1.0000
88.5400 562.0000 1.0000
88.6000 573.0000 1.0000
88.6600 563.0000 1.0000
88.7200 534.0000 1.0000
88.7800 501.0000 1.0000
88.8400 522.0000 1.0000
88.9000 524.0000 1.0000
88.9600 564.0000 1.0000
89.0200 543.0000 1.0000
89.0800 494.0000 1.0000
89.1400 511.0000 1.0000
89.2000 556.0000 1.0000
89.2600 604.0000 1.0000
89.3200 544.0000 1.0000
89.3800 576.0000 1.0000
89.4400 566.0000 1.0000
89.5000 549.0000 1.0000
89.5600 607.0000 1.0000
89.6200 529.0000 1.0000
89.6800 589.0000 1.0000
89.7400 618.0000 1.0000
89.8000 601.0000 1.0000
89.8600 606.0000 1.0000
89.9200 577.0000 1.0000
89.9800 552.0000 1.0000
90.0000 565.0000 1.0000
*RAS_INT_END
*RAS_DATA_END