File: XRD_source_data/Mars.ras
*RAS_DATA_START
*RAS_HEADER_START
*DISP_FMT_X "%.2f"
*DISP_FMT_Y "%.0f"
*DISP_FULLSCALE "2031.6000000000"
*DISP_LINE_COLOR "255.0000000000"
*DISP_LINE_STYLE "0.0000000000"
*DISP_LINE_WIDTH "0.2500000000"
*DISP_NOTE "Collected Data-2"
*DISP_OFFSET_Y "0.0000000000"
*DISP_PEAKSEARCH_UNIT_Y "COUNTS"
*DISP_RANGE_BOTTOM "0.0000000000"
*DISP_RANGE_LEFT "10.0000000000"
*DISP_RANGE_LOGCUTOFF "0.0100000000"
*DISP_RANGE_RIGHT "90.0000000000"
*DISP_RANGE_TOP "2031.6000000000"
*DISP_SCALE_MODE_Y "0.0000000000"
*DISP_TAB_NAME "Theta/2-Theta"
*DISP_TITLE_Y "Intensity"
*DISP_UNIT_Y "COUNTS"
*DISP_WINDOW_NAME "MSG_MACROENGINE"
*FILE_COMMENT " "
*FILE_MD5 ""
*FILE_MEMO " "
*FILE_OPERATOR "Administrator"
*FILE_PART_ID "MEAS_PBEA_00223"
*FILE_SAMPLE "Mars"
*FILE_TYPE "RAS_RAW"
*FILE_USERGROUP "System Manager"
*FILE_VERSION "1.0000000000"
*HW_ATTACHMENT_ID "ATT1031"
*HW_ATTACHMENT_NAME "6サンプルチェンジャ|ASC-6"
*HW_COUNTER_ID-0 "CUT0021"
*HW_COUNTER_ID-1 "CUT0020"
*HW_COUNTER_ID-2 "CUT0020"
*HW_COUNTER_ID-3 "CMC0021"
*HW_COUNTER_NAME-0 "SC-70|SC-70"
*HW_COUNTER_NAME-1 "None|None"
*HW_COUNTER_NAME-2 "None|None"
*HW_COUNTER_NAME-3 "検出器モノクロメータ|Detector monochromator"
*HW_COUNTER_SELECT_NAME "SC-70|SC-70"
*HW_ECP_HV "714.0000000000"
*HW_ECP_HV_UNIT "V"
*HW_GONIOMETER_ID "GON0070"
*HW_GONIOMETER_NAME "MiniFlex 300/600|MiniFlex 300/600"
*HW_GONIOMETER_RADIUS-0 "79.0"
*HW_GONIOMETER_RADIUS-1 "91.5"
*HW_GONIOMETER_RADIUS-2 "150.0"
*HW_GONIOMETER_RADIUS-3 "0"
*HW_GONIOMETER_RADIUS-4 "103.4"
*HW_GONIOMETER_RADIUS-5 "150.0"
*HW_GONIOMETER_RADIUS-6 "46.6"
*HW_GONIOMETER_RADIUS-7 "160.0"
*HW_I_OPT_ID-0 "ISL0021"
*HW_I_OPT_ID-1 "ISO0021"
*HW_I_OPT_NAME-0 "発散スリット|Divergence slit"
*HW_I_OPT_NAME-1 "入射平行スリット|Incident parallel slit"
*HW_R_ATTENUATER_AUTOMODE "0"
*HW_R_OPT_ID-0 "RSS0021"
*HW_R_OPT_ID-1 "RSO0021"
*HW_R_OPT_ID-2 "RRS0021"
*HW_R_OPT_NAME-0 "散乱スリット|Scattering slit"
*HW_R_OPT_NAME-1 "受光平行スリット|Receiving soller slit"
*HW_R_OPT_NAME-2 "受光スリット|Receiving slit"
*HW_SAMPLE_HOLDER_ID "SMP0000"
*HW_SAMPLE_HOLDER_NAME "無し|None"
*HW_XG_CURRENT_MAX "50"
*HW_XG_CURRENT_MIN "2"
*HW_XG_CURRENT_RESOLUTION "2"
*HW_XG_CURRENT_UNIT "mA"
*HW_XG_FOCUS "1mm x 10mm"
*HW_XG_FOCUS_TYPE "Normal"
*HW_XG_ID "1062"
*HW_XG_NAME "300W/600W 封入管-A|300W/600W Sealed tube-A"
*HW_XG_TARGET_ATOMIC_NUMBER "29.0000000000"
*HW_XG_TARGET_NAME "Cu"
*HW_XG_TYPE "Compact"
*HW_XG_VOLTAGE_MAX "60"
*HW_XG_VOLTAGE_MIN "20"
*HW_XG_VOLTAGE_RESOLUTION "2"
*HW_XG_VOLTAGE_UNIT "kV"
*HW_XG_WATT_MAX "2.000"
*HW_XG_WATT_UNIT "kW"
*HW_XG_WAVE_LENGTH_ALPHA1 "1.540593"
*HW_XG_WAVE_LENGTH_ALPHA2 "1.544414"
*HW_XG_WAVE_LENGTH_BETA "1.392250"
*MEAS_COND_AXIS_NAME-0 "Theta/2-Theta"
*MEAS_COND_AXIS_NAME-1 "Spin"
*MEAS_COND_AXIS_NAME-2 "Change"
*MEAS_COND_AXIS_NAME-3 "Soller(inc.)"
*MEAS_COND_AXIS_NAME-4 "IHS"
*MEAS_COND_AXIS_NAME-5 "DS"
*MEAS_COND_AXIS_NAME-6 "SS"
*MEAS_COND_AXIS_NAME-7 "Soller(rec.)"
*MEAS_COND_AXIS_NAME-8 "RS"
*MEAS_COND_AXIS_NAME-9 "Filter"
*MEAS_COND_AXIS_NAME-10 "Monochromator"
*MEAS_COND_AXIS_NAME-11 "HV"
*MEAS_COND_AXIS_NAME-12 "PHA"
*MEAS_COND_AXIS_NAME_INTERNAL-0 "TwoThetaTheta"
*MEAS_COND_AXIS_NAME_INTERNAL-1 "Spin"
*MEAS_COND_AXIS_NAME_INTERNAL-2 "Change"
*MEAS_COND_AXIS_NAME_INTERNAL-3 "IncidentSollerSlit"
*MEAS_COND_AXIS_NAME_INTERNAL-4 "IncidentAxdSlit"
*MEAS_COND_AXIS_NAME_INTERNAL-5 "IncidentSlitBox"
*MEAS_COND_AXIS_NAME_INTERNAL-6 "ReceivingSlitBox1"
*MEAS_COND_AXIS_NAME_INTERNAL-7 "ReceivingSollerSlit"
*MEAS_COND_AXIS_NAME_INTERNAL-8 "ReceivingSlitBox2"
*MEAS_COND_AXIS_NAME_INTERNAL-9 "Filter"
*MEAS_COND_AXIS_NAME_INTERNAL-10 "CounterMonochromator"
*MEAS_COND_AXIS_NAME_INTERNAL-11 "HV"
*MEAS_COND_AXIS_NAME_INTERNAL-12 "PHA"
*MEAS_COND_AXIS_NAME_MAGICNO-0 "268632064.0000000000"
*MEAS_COND_AXIS_NAME_MAGICNO-1 "16842752.0000000000"
*MEAS_COND_AXIS_NAME_MAGICNO-2 "16842752.0000000000"
*MEAS_COND_AXIS_NAME_MAGICNO-3 "20971521.0000000000"
*MEAS_COND_AXIS_NAME_MAGICNO-4 "22020097.0000000000"
*MEAS_COND_AXIS_NAME_MAGICNO-5 "22020097.0000000000"
*MEAS_COND_AXIS_NAME_MAGICNO-6 "23068673.0000000000"
*MEAS_COND_AXIS_NAME_MAGICNO-7 "20971521.0000000000"
*MEAS_COND_AXIS_NAME_MAGICNO-8 "23068673.0000000000"
*MEAS_COND_AXIS_NAME_MAGICNO-9 "20971521.0000000000"
*MEAS_COND_AXIS_NAME_MAGICNO-10 "20971521.0000000000"
*MEAS_COND_AXIS_NAME_MAGICNO-11 "0.0000000000"
*MEAS_COND_AXIS_NAME_MAGICNO-12 "0.0000000000"
*MEAS_COND_AXIS_OFFSET-0 "0.0000000000"
*MEAS_COND_AXIS_OFFSET-1 "-"
*MEAS_COND_AXIS_OFFSET-2 "-"
*MEAS_COND_AXIS_OFFSET-3 "-"
*MEAS_COND_AXIS_OFFSET-4 "-"
*MEAS_COND_AXIS_OFFSET-5 "-"
*MEAS_COND_AXIS_OFFSET-6 "-"
*MEAS_COND_AXIS_OFFSET-7 "-"
*MEAS_COND_AXIS_OFFSET-8 "-"
*MEAS_COND_AXIS_OFFSET-9 "-"
*MEAS_COND_AXIS_OFFSET-10 "-"
*MEAS_COND_AXIS_OFFSET-11 "-"
*MEAS_COND_AXIS_OFFSET-12 "-"
*MEAS_COND_AXIS_POSITION-0 "90.0100000000"
*MEAS_COND_AXIS_POSITION-1 "0.0000000000"
*MEAS_COND_AXIS_POSITION-2 "4.0000000000"
*MEAS_COND_AXIS_POSITION-3 "2.5deg"
*MEAS_COND_AXIS_POSITION-4 "10.0mm"
*MEAS_COND_AXIS_POSITION-5 "1.250deg"
*MEAS_COND_AXIS_POSITION-6 "13.0mm(Open)"
*MEAS_COND_AXIS_POSITION-7 "5.0deg"
*MEAS_COND_AXIS_POSITION-8 "13.0mm"
*MEAS_COND_AXIS_POSITION-9 "None"
*MEAS_COND_AXIS_POSITION-10 "None"
*MEAS_COND_AXIS_POSITION-11 "714.0000000000"
*MEAS_COND_AXIS_POSITION-12 "568.7500000000"
*MEAS_COND_AXIS_UNIT-0 "deg"
*MEAS_COND_AXIS_UNIT-1 ""
*MEAS_COND_AXIS_UNIT-2 ""
*MEAS_COND_AXIS_UNIT-3 ""
*MEAS_COND_AXIS_UNIT-4 ""
*MEAS_COND_AXIS_UNIT-5 ""
*MEAS_COND_AXIS_UNIT-6 ""
*MEAS_COND_AXIS_UNIT-7 ""
*MEAS_COND_AXIS_UNIT-8 ""
*MEAS_COND_AXIS_UNIT-9 ""
*MEAS_COND_AXIS_UNIT-10 ""
*MEAS_COND_AXIS_UNIT-11 "V"
*MEAS_COND_AXIS_UNIT-12 "mV"
*MEAS_COND_CORRECTION_SLIT_COUNTERMONO "None"
*MEAS_COND_CORRECTION_SLIT_DS "1.250deg"
*MEAS_COND_CORRECTION_SLIT_FILTER "None"
*MEAS_COND_CORRECTION_SLIT_IHS "10.0mm"
*MEAS_COND_CORRECTION_SLIT_RS "13.0mm"
*MEAS_COND_CORRECTION_SLIT_SOLLER_INC "2.5deg"
*MEAS_COND_CORRECTION_SLIT_SOLLER_REC "5.0deg"
*MEAS_COND_CORRECTION_SLIT_SS "13.0mm"
*MEAS_COND_COUNTER_CNTLOSS_CORR "0.0000000000"
*MEAS_COND_COUNTER_PHABASE "568.7500000000"
*MEAS_COND_COUNTER_PHAWINDOW "926.2500000000"
*MEAS_COND_COUNTER_PHA_UNIT "mV"
*MEAS_COND_COUNTER_TAUDIFF "0.2500000000"
*MEAS_COND_COUNTER_TAUINT "0.7500000000"
*MEAS_COND_IRRADIATION_MODE "OFF"
*MEAS_COND_IRRADIATION_WIDTH ""
*MEAS_COND_OPT_ATTR " "
*MEAS_COND_OPT_NAME ""
*MEAS_COND_UNSYMMETRIC_MODE "OFF"
*MEAS_COND_XG_CURRENT "15.0000000000"
*MEAS_COND_XG_VOLTAGE "40.0000000000"
*MEAS_COND_XG_WAVE_TYPE "Ka"
*MEAS_DATA_COUNT "4001.0000000000"
*MEAS_SCAN_AXIS_X "Theta/2-Theta"
*MEAS_SCAN_AXIS_X_INTERNAL "TwoThetaTheta"
*MEAS_SCAN_END_TIME "03/07/24 15:18:39"
*MEAS_SCAN_MODE "CONTINUOUS"
*MEAS_SCAN_MONITOR "0"
*MEAS_SCAN_RESOLUTION_X "0.0025"
*MEAS_SCAN_SPEED "2.0000"
*MEAS_SCAN_SPEED_UNIT "deg/min"
*MEAS_SCAN_SPEED_USER "2.0000"
*MEAS_SCAN_START "10.0000000000"
*MEAS_SCAN_START_TIME "03/07/24 14:38:21"
*MEAS_SCAN_STEP "0.0200000000"
*MEAS_SCAN_STOP "90.0000000000"
*MEAS_SCAN_UNIT_X "deg"
*MEAS_SCAN_UNIT_Y "counts"
*SLIT_SYSTEM "0"
*RAS_HEADER_END
*RAS_INT_START
10.0000 327.0000 1.0000
10.0600 346.0000 1.0000
10.1200 329.0000 1.0000
10.1800 354.0000 1.0000
10.2400 327.0000 1.0000
10.3000 356.0000 1.0000
10.3600 337.0000 1.0000
10.4200 323.0000 1.0000
10.4800 310.0000 1.0000
10.5400 362.0000 1.0000
10.6000 339.0000 1.0000
10.6600 337.0000 1.0000
10.7200 345.0000 1.0000
10.7800 288.0000 1.0000
10.8400 340.0000 1.0000
10.9000 326.0000 1.0000
10.9600 362.0000 1.0000
11.0200 316.0000 1.0000
11.0800 339.0000 1.0000
11.1400 295.0000 1.0000
11.2000 377.0000 1.0000
11.2600 296.0000 1.0000
11.3200 329.0000 1.0000
11.3800 317.0000 1.0000
11.4400 333.0000 1.0000
11.5000 320.0000 1.0000
11.5600 294.0000 1.0000
11.6200 275.0000 1.0000
11.6800 279.0000 1.0000
11.7400 320.0000 1.0000
11.8000 293.0000 1.0000
11.8600 304.0000 1.0000
11.9200 369.0000 1.0000
11.9800 333.0000 1.0000
12.0400 311.0000 1.0000
12.1000 309.0000 1.0000
12.1600 320.0000 1.0000
12.2200 285.0000 1.0000
12.2800 303.0000 1.0000
12.3400 362.0000 1.0000
12.4000 354.0000 1.0000
12.4600 332.0000 1.0000
12.5200 365.0000 1.0000
12.5800 311.0000 1.0000
12.6400 311.0000 1.0000
12.7000 278.0000 1.0000
12.7600 320.0000 1.0000
12.8200 263.0000 1.0000
12.8800 312.0000 1.0000
12.9400 295.0000 1.0000
13.0000 269.0000 1.0000
13.0600 244.0000 1.0000
13.1200 275.0000 1.0000
13.1800 233.0000 1.0000
13.2400 293.0000 1.0000
13.3000 269.0000 1.0000
13.3600 262.0000 1.0000
13.4200 286.0000 1.0000
13.4800 265.0000 1.0000
13.5400 286.0000 1.0000
13.6000 274.0000 1.0000
13.6600 241.0000 1.0000
13.7200 255.0000 1.0000
13.7800 259.0000 1.0000
13.8400 281.0000 1.0000
13.9000 260.0000 1.0000
13.9600 280.0000 1.0000
14.0200 255.0000 1.0000
14.0800 267.0000 1.0000
14.1400 229.0000 1.0000
14.2000 248.0000 1.0000
14.2600 248.0000 1.0000
14.3200 248.0000 1.0000
14.3800 256.0000 1.0000
14.4400 233.0000 1.0000
14.5000 249.0000 1.0000
14.5600 261.0000 1.0000
14.6200 228.0000 1.0000
14.6800 255.0000 1.0000
14.7400 236.0000 1.0000
14.8000 244.0000 1.0000
14.8600 239.0000 1.0000
14.9200 218.0000 1.0000
14.9800 247.0000 1.0000
15.0400 253.0000 1.0000
15.1000 226.0000 1.0000
15.1600 237.0000 1.0000
15.2200 240.0000 1.0000
15.2800 218.0000 1.0000
15.3400 247.0000 1.0000
15.4000 236.0000 1.0000
15.4600 224.0000 1.0000
15.5200 227.0000 1.0000
15.5800 243.0000 1.0000
15.6400 214.0000 1.0000
15.7000 215.0000 1.0000
15.7600 200.0000 1.0000
15.8200 238.0000 1.0000
15.8800 202.0000 1.0000
15.9400 209.0000 1.0000
16.0000 233.0000 1.0000
16.0600 257.0000 1.0000
16.1200 234.0000 1.0000
16.1800 201.0000 1.0000
16.2400 180.0000 1.0000
16.3000 252.0000 1.0000
16.3600 218.0000 1.0000
16.4200 217.0000 1.0000
16.4800 218.0000 1.0000
16.5400 183.0000 1.0000
16.6000 204.0000 1.0000
16.6600 183.0000 1.0000
16.7200 223.0000 1.0000
16.7800 170.0000 1.0000
16.8400 224.0000 1.0000
16.9000 205.0000 1.0000
16.9600 220.0000 1.0000
17.0200 221.0000 1.0000
17.0800 208.0000 1.0000
17.1400 183.0000 1.0000
17.2000 214.0000 1.0000
17.2600 217.0000 1.0000
17.3200 200.0000 1.0000
17.3800 201.0000 1.0000
17.4400 210.0000 1.0000
17.5000 196.0000 1.0000
17.5600 202.0000 1.0000
17.6200 195.0000 1.0000
17.6800 183.0000 1.0000
17.7400 185.0000 1.0000
17.8000 191.0000 1.0000
17.8600 205.0000 1.0000
17.9200 216.0000 1.0000
17.9800 216.0000 1.0000
18.0400 189.0000 1.0000
18.1000 199.0000 1.0000
18.1600 195.0000 1.0000
18.2200 196.0000 1.0000
18.2800 169.0000 1.0000
18.3400 192.0000 1.0000
18.4000 208.0000 1.0000
18.4600 203.0000 1.0000
18.5200 202.0000 1.0000
18.5800 199.0000 1.0000
18.6400 185.0000 1.0000
18.7000 212.0000 1.0000
18.7600 198.0000 1.0000
18.8200 207.0000 1.0000
18.8800 201.0000 1.0000
18.9400 208.0000 1.0000
19.0000 197.0000 1.0000
19.0600 184.0000 1.0000
19.1200 179.0000 1.0000
19.1800 184.0000 1.0000
19.2400 183.0000 1.0000
19.3000 192.0000 1.0000
19.3600 199.0000 1.0000
19.4200 196.0000 1.0000
19.4800 191.0000 1.0000
19.5400 191.0000 1.0000
19.6000 198.0000 1.0000
19.6600 208.0000 1.0000
19.7200 192.0000 1.0000
19.7800 185.0000 1.0000
19.8400 191.0000 1.0000
19.9000 217.0000 1.0000
19.9600 198.0000 1.0000
20.0200 213.0000 1.0000
20.0800 186.0000 1.0000
20.1400 203.0000 1.0000
20.2000 181.0000 1.0000
20.2600 208.0000 1.0000
20.3200 195.0000 1.0000
20.3800 168.0000 1.0000
20.4400 204.0000 1.0000
20.5000 178.0000 1.0000
20.5600 196.0000 1.0000
20.6200 205.0000 1.0000
20.6800 215.0000 1.0000
20.7400 197.0000 1.0000
20.8000 235.0000 1.0000
20.8600 270.0000 1.0000
20.9200 483.0000 1.0000
20.9800 619.0000 1.0000
21.0400 474.0000 1.0000
21.1000 316.0000 1.0000
21.1600 241.0000 1.0000
21.2200 225.0000 1.0000
21.2800 200.0000 1.0000
21.3400 215.0000 1.0000
21.4000 192.0000 1.0000
21.4600 216.0000 1.0000
21.5200 226.0000 1.0000
21.5800 205.0000 1.0000
21.6400 189.0000 1.0000
21.7000 190.0000 1.0000
21.7600 182.0000 1.0000
21.8200 186.0000 1.0000
21.8800 186.0000 1.0000
21.9400 187.0000 1.0000
22.0000 200.0000 1.0000
22.0600 203.0000 1.0000
22.1200 220.0000 1.0000
22.1800 183.0000 1.0000
22.2400 223.0000 1.0000
22.3000 199.0000 1.0000
22.3600 193.0000 1.0000
22.4200 204.0000 1.0000
22.4800 187.0000 1.0000
22.5400 218.0000 1.0000
22.6000 203.0000 1.0000
22.6600 210.0000 1.0000
22.7200 190.0000 1.0000
22.7800 184.0000 1.0000
22.8400 187.0000 1.0000
22.9000 194.0000 1.0000
22.9600 185.0000 1.0000
23.0200 162.0000 1.0000
23.0800 179.0000 1.0000
23.1400 165.0000 1.0000
23.2000 201.0000 1.0000
23.2600 182.0000 1.0000
23.3200 179.0000 1.0000
23.3800 165.0000 1.0000
23.4400 182.0000 1.0000
23.5000 168.0000 1.0000
23.5600 181.0000 1.0000
23.6200 195.0000 1.0000
23.6800 197.0000 1.0000
23.7400 195.0000 1.0000
23.8000 200.0000 1.0000
23.8600 204.0000 1.0000
23.9200 192.0000 1.0000
23.9800 194.0000 1.0000
24.0400 205.0000 1.0000
24.1000 207.0000 1.0000
24.1600 210.0000 1.0000
24.2200 195.0000 1.0000
24.2800 196.0000 1.0000
24.3400 183.0000 1.0000
24.4000 180.0000 1.0000
24.4600 213.0000 1.0000
24.5200 207.0000 1.0000
24.5800 185.0000 1.0000
24.6400 188.0000 1.0000
24.7000 169.0000 1.0000
24.7600 215.0000 1.0000
24.8200 218.0000 1.0000
24.8800 212.0000 1.0000
24.9400 210.0000 1.0000
25.0000 198.0000 1.0000
25.0600 235.0000 1.0000
25.1200 220.0000 1.0000
25.1800 193.0000 1.0000
25.2400 204.0000 1.0000
25.3000 197.0000 1.0000
25.3600 200.0000 1.0000
25.4200 197.0000 1.0000
25.4800 162.0000 1.0000
25.5400 174.0000 1.0000
25.6000 200.0000 1.0000
25.6600 184.0000 1.0000
25.7200 198.0000 1.0000
25.7800 231.0000 1.0000
25.8400 173.0000 1.0000
25.9000 202.0000 1.0000
25.9600 187.0000 1.0000
26.0200 179.0000 1.0000
26.0800 209.0000 1.0000
26.1400 211.0000 1.0000
26.2000 178.0000 1.0000
26.2600 200.0000 1.0000
26.3200 225.0000 1.0000
26.3800 224.0000 1.0000
26.4400 209.0000 1.0000
26.5000 244.0000 1.0000
26.5600 237.0000 1.0000
26.6200 352.0000 1.0000
26.6800 775.0000 1.0000
26.7400 1507.0000 1.0000
26.8000 1500.0000 1.0000
26.8600 815.0000 1.0000
26.9200 451.0000 1.0000
26.9800 400.0000 1.0000
27.0400 403.0000 1.0000
27.1000 252.0000 1.0000
27.1600 183.0000 1.0000
27.2200 221.0000 1.0000
27.2800 194.0000 1.0000
27.3400 211.0000 1.0000
27.4000 226.0000 1.0000
27.4600 203.0000 1.0000
27.5200 213.0000 1.0000
27.5800 212.0000 1.0000
27.6400 238.0000 1.0000
27.7000 298.0000 1.0000
27.7600 262.0000 1.0000
27.8200 238.0000 1.0000
27.8800 226.0000 1.0000
27.9400 185.0000 1.0000
28.0000 197.0000 1.0000
28.0600 239.0000 1.0000
28.1200 219.0000 1.0000
28.1800 178.0000 1.0000
28.2400 207.0000 1.0000
28.3000 195.0000 1.0000
28.3600 194.0000 1.0000
28.4200 203.0000 1.0000
28.4800 179.0000 1.0000
28.5400 200.0000 1.0000
28.6000 171.0000 1.0000
28.6600 164.0000 1.0000
28.7200 188.0000 1.0000
28.7800 190.0000 1.0000
28.8400 173.0000 1.0000
28.9000 178.0000 1.0000
28.9600 195.0000 1.0000
29.0200 194.0000 1.0000
29.0800 190.0000 1.0000
29.1400 167.0000 1.0000
29.2000 180.0000 1.0000
29.2600 183.0000 1.0000
29.3200 202.0000 1.0000
29.3800 193.0000 1.0000
29.4400 163.0000 1.0000
29.5000 175.0000 1.0000
29.5600 196.0000 1.0000
29.6200 204.0000 1.0000
29.6800 191.0000 1.0000
29.7400 195.0000 1.0000
29.8000 193.0000 1.0000
29.8600 195.0000 1.0000
29.9200 187.0000 1.0000
29.9800 203.0000 1.0000
30.0400 176.0000 1.0000
30.1000 190.0000 1.0000
30.1600 165.0000 1.0000
30.2200 182.0000 1.0000
30.2800 188.0000 1.0000
30.3400 198.0000 1.0000
30.4000 167.0000 1.0000
30.4600 197.0000 1.0000
30.5200 187.0000 1.0000
30.5800 175.0000 1.0000
30.6400 191.0000 1.0000
30.7000 175.0000 1.0000
30.7600 173.0000 1.0000
30.8200 176.0000 1.0000
30.8800 195.0000 1.0000
30.9400 174.0000 1.0000
31.0000 182.0000 1.0000
31.0600 176.0000 1.0000
31.1200 172.0000 1.0000
31.1800 188.0000 1.0000
31.2400 171.0000 1.0000
31.3000 185.0000 1.0000
31.3600 200.0000 1.0000
31.4200 181.0000 1.0000
31.4800 182.0000 1.0000
31.5400 183.0000 1.0000
31.6000 169.0000 1.0000
31.6600 164.0000 1.0000
31.7200 202.0000 1.0000
31.7800 172.0000 1.0000
31.8400 176.0000 1.0000
31.9000 177.0000 1.0000
31.9600 144.0000 1.0000
32.0200 175.0000 1.0000
32.0800 168.0000 1.0000
32.1400 185.0000 1.0000
32.2000 177.0000 1.0000
32.2600 175.0000 1.0000
32.3200 178.0000 1.0000
32.3800 179.0000 1.0000
32.4400 164.0000 1.0000
32.5000 198.0000 1.0000
32.5600 176.0000 1.0000
32.6200 190.0000 1.0000
32.6800 188.0000 1.0000
32.7400 199.0000 1.0000
32.8000 176.0000 1.0000
32.8600 171.0000 1.0000
32.9200 207.0000 1.0000
32.9800 176.0000 1.0000
33.0400 183.0000 1.0000
33.1000 193.0000 1.0000
33.1600 206.0000 1.0000
33.2200 183.0000 1.0000
33.2800 191.0000 1.0000
33.3400 193.0000 1.0000
33.4000 200.0000 1.0000
33.4600 171.0000 1.0000
33.5200 202.0000 1.0000
33.5800 158.0000 1.0000
33.6400 169.0000 1.0000
33.7000 171.0000 1.0000
33.7600 187.0000 1.0000
33.8200 198.0000 1.0000
33.8800 180.0000 1.0000
33.9400 198.0000 1.0000
34.0000 190.0000 1.0000
34.0600 200.0000 1.0000
34.1200 179.0000 1.0000
34.1800 177.0000 1.0000
34.2400 205.0000 1.0000
34.3000 176.0000 1.0000
34.3600 174.0000 1.0000
34.4200 212.0000 1.0000
34.4800 190.0000 1.0000
34.5400 199.0000 1.0000
34.6000 218.0000 1.0000
34.6600 171.0000 1.0000
34.7200 188.0000 1.0000
34.7800 200.0000 1.0000
34.8400 214.0000 1.0000
34.9000 198.0000 1.0000
34.9600 187.0000 1.0000
35.0200 170.0000 1.0000
35.0800 197.0000 1.0000
35.1400 190.0000 1.0000
35.2000 202.0000 1.0000
35.2600 230.0000 1.0000
35.3200 231.0000 1.0000
35.3800 239.0000 1.0000
35.4400 235.0000 1.0000
35.5000 239.0000 1.0000
35.5600 229.0000 1.0000
35.6200 204.0000 1.0000
35.6800 226.0000 1.0000
35.7400 223.0000 1.0000
35.8000 214.0000 1.0000
35.8600 225.0000 1.0000
35.9200 201.0000 1.0000
35.9800 219.0000 1.0000
36.0400 192.0000 1.0000
36.1000 205.0000 1.0000
36.1600 200.0000 1.0000
36.2200 184.0000 1.0000
36.2800 194.0000 1.0000
36.3400 198.0000 1.0000
36.4000 205.0000 1.0000
36.4600 216.0000 1.0000
36.5200 200.0000 1.0000
36.5800 254.0000 1.0000
36.6400 308.0000 1.0000
36.7000 323.0000 1.0000
36.7600 263.0000 1.0000
36.8200 244.0000 1.0000
36.8800 219.0000 1.0000
36.9400 179.0000 1.0000
37.0000 207.0000 1.0000
37.0600 164.0000 1.0000
37.1200 177.0000 1.0000
37.1800 174.0000 1.0000
37.2400 193.0000 1.0000
37.3000 193.0000 1.0000
37.3600 174.0000 1.0000
37.4200 202.0000 1.0000
37.4800 181.0000 1.0000
37.5400 176.0000 1.0000
37.6000 164.0000 1.0000
37.6600 186.0000 1.0000
37.7200 154.0000 1.0000
37.7800 190.0000 1.0000
37.8400 177.0000 1.0000
37.9000 183.0000 1.0000
37.9600 171.0000 1.0000
38.0200 183.0000 1.0000
38.0800 176.0000 1.0000
38.1400 157.0000 1.0000
38.2000 165.0000 1.0000
38.2600 163.0000 1.0000
38.3200 170.0000 1.0000
38.3800 158.0000 1.0000
38.4400 158.0000 1.0000
38.5000 171.0000 1.0000
38.5600 183.0000 1.0000
38.6200 189.0000 1.0000
38.6800 159.0000 1.0000
38.7400 180.0000 1.0000
38.8000 173.0000 1.0000
38.8600 177.0000 1.0000
38.9200 167.0000 1.0000
38.9800 166.0000 1.0000
39.0400 188.0000 1.0000
39.1000 186.0000 1.0000
39.1600 162.0000 1.0000
39.2200 185.0000 1.0000
39.2800 146.0000 1.0000
39.3400 181.0000 1.0000
39.4000 195.0000 1.0000
39.4600 191.0000 1.0000
39.5200 219.0000 1.0000
39.5800 239.0000 1.0000
39.6400 222.0000 1.0000
39.7000 201.0000 1.0000
39.7600 177.0000 1.0000
39.8200 163.0000 1.0000
39.8800 159.0000 1.0000
39.9400 169.0000 1.0000
40.0000 174.0000 1.0000
40.0600 179.0000 1.0000
40.1200 179.0000 1.0000
40.1800 186.0000 1.0000
40.2400 176.0000 1.0000
40.3000 180.0000 1.0000
40.3600 182.0000 1.0000
40.4200 203.0000 1.0000
40.4800 221.0000 1.0000
40.5400 192.0000 1.0000
40.6000 163.0000 1.0000
40.6600 190.0000 1.0000
40.7200 166.0000 1.0000
40.7800 167.0000 1.0000
40.8400 163.0000 1.0000
40.9000 205.0000 1.0000
40.9600 180.0000 1.0000
41.0200 185.0000 1.0000
41.0800 191.0000 1.0000
41.1400 170.0000 1.0000
41.2000 167.0000 1.0000
41.2600 188.0000 1.0000
41.3200 194.0000 1.0000
41.3800 163.0000 1.0000
41.4400 175.0000 1.0000
41.5000 170.0000 1.0000
41.5600 186.0000 1.0000
41.6200 173.0000 1.0000
41.6800 171.0000 1.0000
41.7400 180.0000 1.0000
41.8000 193.0000 1.0000
41.8600 185.0000 1.0000
41.9200 194.0000 1.0000
41.9800 181.0000 1.0000
42.0400 194.0000 1.0000
42.1000 172.0000 1.0000
42.1600 169.0000 1.0000
42.2200 167.0000 1.0000
42.2800 158.0000 1.0000
42.3400 157.0000 1.0000
42.4000 162.0000 1.0000
42.4600 197.0000 1.0000
42.5200 235.0000 1.0000
42.5800 228.0000 1.0000
42.6400 200.0000 1.0000
42.7000 218.0000 1.0000
42.7600 196.0000 1.0000
42.8200 168.0000 1.0000
42.8800 186.0000 1.0000
42.9400 163.0000 1.0000
43.0000 176.0000 1.0000
43.0600 172.0000 1.0000
43.1200 162.0000 1.0000
43.1800 172.0000 1.0000
43.2400 144.0000 1.0000
43.3000 168.0000 1.0000
43.3600 170.0000 1.0000
43.4200 167.0000 1.0000
43.4800 159.0000 1.0000
43.5400 183.0000 1.0000
43.6000 176.0000 1.0000
43.6600 160.0000 1.0000
43.7200 176.0000 1.0000
43.7800 175.0000 1.0000
43.8400 169.0000 1.0000
43.9000 161.0000 1.0000
43.9600 160.0000 1.0000
44.0200 165.0000 1.0000
44.0800 208.0000 1.0000
44.1400 172.0000 1.0000
44.2000 140.0000 1.0000
44.2600 173.0000 1.0000
44.3200 172.0000 1.0000
44.3800 181.0000 1.0000
44.4400 172.0000 1.0000
44.5000 165.0000 1.0000
44.5600 190.0000 1.0000
44.6200 162.0000 1.0000
44.6800 154.0000 1.0000
44.7400 144.0000 1.0000
44.8000 156.0000 1.0000
44.8600 173.0000 1.0000
44.9200 160.0000 1.0000
44.9800 170.0000 1.0000
45.0400 169.0000 1.0000
45.1000 144.0000 1.0000
45.1600 179.0000 1.0000
45.2200 157.0000 1.0000
45.2800 179.0000 1.0000
45.3400 173.0000 1.0000
45.4000 169.0000 1.0000
45.4600 156.0000 1.0000
45.5200 160.0000 1.0000
45.5800 167.0000 1.0000
45.6400 170.0000 1.0000
45.7000 170.0000 1.0000
45.7600 181.0000 1.0000
45.8200 218.0000 1.0000
45.8800 213.0000 1.0000
45.9400 227.0000 1.0000
46.0000 198.0000 1.0000
46.0600 178.0000 1.0000
46.1200 173.0000 1.0000
46.1800 164.0000 1.0000
46.2400 190.0000 1.0000
46.3000 150.0000 1.0000
46.3600 214.0000 1.0000
46.4200 163.0000 1.0000
46.4800 140.0000 1.0000
46.5400 166.0000 1.0000
46.6000 159.0000 1.0000
46.6600 148.0000 1.0000
46.7200 174.0000 1.0000
46.7800 168.0000 1.0000
46.8400 163.0000 1.0000
46.9000 176.0000 1.0000
46.9600 163.0000 1.0000
47.0200 177.0000 1.0000
47.0800 184.0000 1.0000
47.1400 174.0000 1.0000
47.2000 156.0000 1.0000
47.2600 156.0000 1.0000
47.3200 173.0000 1.0000
47.3800 151.0000 1.0000
47.4400 174.0000 1.0000
47.5000 167.0000 1.0000
47.5600 177.0000 1.0000
47.6200 174.0000 1.0000
47.6800 188.0000 1.0000
47.7400 181.0000 1.0000
47.8000 170.0000 1.0000
47.8600 165.0000 1.0000
47.9200 162.0000 1.0000
47.9800 168.0000 1.0000
48.0400 189.0000 1.0000
48.1000 184.0000 1.0000
48.1600 186.0000 1.0000
48.2200 183.0000 1.0000
48.2800 180.0000 1.0000
48.3400 171.0000 1.0000
48.4000 160.0000 1.0000
48.4600 163.0000 1.0000
48.5200 191.0000 1.0000
48.5800 163.0000 1.0000
48.6400 166.0000 1.0000
48.7000 164.0000 1.0000
48.7600 165.0000 1.0000
48.8200 168.0000 1.0000
48.8800 161.0000 1.0000
48.9400 169.0000 1.0000
49.0000 166.0000 1.0000
49.0600 156.0000 1.0000
49.1200 167.0000 1.0000
49.1800 188.0000 1.0000
49.2400 174.0000 1.0000
49.3000 188.0000 1.0000
49.3600 146.0000 1.0000
49.4200 168.0000 1.0000
49.4800 173.0000 1.0000
49.5400 164.0000 1.0000
49.6000 163.0000 1.0000
49.6600 196.0000 1.0000
49.7200 197.0000 1.0000
49.7800 179.0000 1.0000
49.8400 158.0000 1.0000
49.9000 168.0000 1.0000
49.9600 186.0000 1.0000
50.0200 142.0000 1.0000
50.0800 218.0000 1.0000
50.1400 241.0000 1.0000
50.2000 336.0000 1.0000
50.2600 312.0000 1.0000
50.3200 276.0000 1.0000
50.3800 248.0000 1.0000
50.4400 201.0000 1.0000
50.5000 197.0000 1.0000
50.5600 175.0000 1.0000
50.6200 160.0000 1.0000
50.6800 195.0000 1.0000
50.7400 197.0000 1.0000
50.8000 232.0000 1.0000
50.8600 220.0000 1.0000
50.9200 191.0000 1.0000
50.9800 194.0000 1.0000
51.0400 172.0000 1.0000
51.1000 159.0000 1.0000
51.1600 167.0000 1.0000
51.2200 169.0000 1.0000
51.2800 176.0000 1.0000
51.3400 164.0000 1.0000
51.4000 177.0000 1.0000
51.4600 168.0000 1.0000
51.5200 153.0000 1.0000
51.5800 175.0000 1.0000
51.6400 166.0000 1.0000
51.7000 175.0000 1.0000
51.7600 155.0000 1.0000
51.8200 149.0000 1.0000
51.8800 172.0000 1.0000
51.9400 138.0000 1.0000
52.0000 158.0000 1.0000
52.0600 180.0000 1.0000
52.1200 169.0000 1.0000
52.1800 144.0000 1.0000
52.2400 164.0000 1.0000
52.3000 169.0000 1.0000
52.3600 183.0000 1.0000
52.4200 164.0000 1.0000
52.4800 157.0000 1.0000
52.5400 155.0000 1.0000
52.6000 158.0000 1.0000
52.6600 186.0000 1.0000
52.7200 158.0000 1.0000
52.7800 171.0000 1.0000
52.8400 148.0000 1.0000
52.9000 144.0000 1.0000
52.9600 163.0000 1.0000
53.0200 153.0000 1.0000
53.0800 166.0000 1.0000
53.1400 157.0000 1.0000
53.2000 158.0000 1.0000
53.2600 198.0000 1.0000
53.3200 159.0000 1.0000
53.3800 194.0000 1.0000
53.4400 174.0000 1.0000
53.5000 175.0000 1.0000
53.5600 171.0000 1.0000
53.6200 183.0000 1.0000
53.6800 157.0000 1.0000
53.7400 174.0000 1.0000
53.8000 161.0000 1.0000
53.8600 154.0000 1.0000
53.9200 170.0000 1.0000
53.9800 141.0000 1.0000
54.0400 160.0000 1.0000
54.1000 176.0000 1.0000
54.1600 172.0000 1.0000
54.2200 191.0000 1.0000
54.2800 185.0000 1.0000
54.3400 180.0000 1.0000
54.4000 174.0000 1.0000
54.4600 170.0000 1.0000
54.5200 166.0000 1.0000
54.5800 179.0000 1.0000
54.6400 167.0000 1.0000
54.7000 183.0000 1.0000
54.7600 163.0000 1.0000
54.8200 182.0000 1.0000
54.8800 185.0000 1.0000
54.9400 205.0000 1.0000
55.0000 215.0000 1.0000
55.0600 180.0000 1.0000
55.1200 203.0000 1.0000
55.1800 203.0000 1.0000
55.2400 170.0000 1.0000
55.3000 178.0000 1.0000
55.3600 148.0000 1.0000
55.4200 179.0000 1.0000
55.4800 187.0000 1.0000
55.5400 164.0000 1.0000
55.6000 169.0000 1.0000
55.6600 155.0000 1.0000
55.7200 160.0000 1.0000
55.7800 133.0000 1.0000
55.8400 185.0000 1.0000
55.9000 157.0000 1.0000
55.9600 161.0000 1.0000
56.0200 193.0000 1.0000
56.0800 149.0000 1.0000
56.1400 154.0000 1.0000
56.2000 175.0000 1.0000
56.2600 149.0000 1.0000
56.3200 185.0000 1.0000
56.3800 168.0000 1.0000
56.4400 165.0000 1.0000
56.5000 138.0000 1.0000
56.5600 165.0000 1.0000
56.6200 161.0000 1.0000
56.6800 170.0000 1.0000
56.7400 165.0000 1.0000
56.8000 171.0000 1.0000
56.8600 158.0000 1.0000
56.9200 151.0000 1.0000
56.9800 186.0000 1.0000
57.0400 166.0000 1.0000
57.1000 163.0000 1.0000
57.1600 183.0000 1.0000
57.2200 154.0000 1.0000
57.2800 167.0000 1.0000
57.3400 193.0000 1.0000
57.4000 153.0000 1.0000
57.4600 167.0000 1.0000
57.5200 195.0000 1.0000
57.5800 151.0000 1.0000
57.6400 157.0000 1.0000
57.7000 165.0000 1.0000
57.7600 165.0000 1.0000
57.8200 173.0000 1.0000
57.8800 162.0000 1.0000
57.9400 164.0000 1.0000
58.0000 166.0000 1.0000
58.0600 151.0000 1.0000
58.1200 171.0000 1.0000
58.1800 151.0000 1.0000
58.2400 143.0000 1.0000
58.3000 161.0000 1.0000
58.3600 155.0000 1.0000
58.4200 172.0000 1.0000
58.4800 194.0000 1.0000
58.5400 165.0000 1.0000
58.6000 185.0000 1.0000
58.6600 174.0000 1.0000
58.7200 153.0000 1.0000
58.7800 189.0000 1.0000
58.8400 140.0000 1.0000
58.9000 157.0000 1.0000
58.9600 176.0000 1.0000
59.0200 187.0000 1.0000
59.0800 151.0000 1.0000
59.1400 164.0000 1.0000
59.2000 171.0000 1.0000
59.2600 155.0000 1.0000
59.3200 183.0000 1.0000
59.3800 177.0000 1.0000
59.4400 166.0000 1.0000
59.5000 161.0000 1.0000
59.5600 174.0000 1.0000
59.6200 177.0000 1.0000
59.6800 156.0000 1.0000
59.7400 156.0000 1.0000
59.8000 191.0000 1.0000
59.8600 160.0000 1.0000
59.9200 175.0000 1.0000
59.9800 228.0000 1.0000
60.0400 224.0000 1.0000
60.1000 200.0000 1.0000
60.1600 205.0000 1.0000
60.2200 170.0000 1.0000
60.2800 180.0000 1.0000
60.3400 147.0000 1.0000
60.4000 168.0000 1.0000
60.4600 164.0000 1.0000
60.5200 153.0000 1.0000
60.5800 158.0000 1.0000
60.6400 170.0000 1.0000
60.7000 158.0000 1.0000
60.7600 156.0000 1.0000
60.8200 141.0000 1.0000
60.8800 162.0000 1.0000
60.9400 163.0000 1.0000
61.0000 146.0000 1.0000
61.0600 161.0000 1.0000
61.1200 179.0000 1.0000
61.1800 159.0000 1.0000
61.2400 139.0000 1.0000
61.3000 179.0000 1.0000
61.3600 191.0000 1.0000
61.4200 160.0000 1.0000
61.4800 161.0000 1.0000
61.5400 190.0000 1.0000
61.6000 164.0000 1.0000
61.6600 153.0000 1.0000
61.7200 192.0000 1.0000
61.7800 169.0000 1.0000
61.8400 168.0000 1.0000
61.9000 190.0000 1.0000
61.9600 155.0000 1.0000
62.0200 154.0000 1.0000
62.0800 180.0000 1.0000
62.1400 186.0000 1.0000
62.2000 179.0000 1.0000
62.2600 159.0000 1.0000
62.3200 159.0000 1.0000
62.3800 163.0000 1.0000
62.4400 180.0000 1.0000
62.5000 144.0000 1.0000
62.5600 165.0000 1.0000
62.6200 164.0000 1.0000
62.6800 197.0000 1.0000
62.7400 171.0000 1.0000
62.8000 162.0000 1.0000
62.8600 179.0000 1.0000
62.9200 169.0000 1.0000
62.9800 173.0000 1.0000
63.0400 175.0000 1.0000
63.1000 179.0000 1.0000
63.1600 184.0000 1.0000
63.2200 167.0000 1.0000
63.2800 146.0000 1.0000
63.3400 186.0000 1.0000
63.4000 172.0000 1.0000
63.4600 180.0000 1.0000
63.5200 157.0000 1.0000
63.5800 149.0000 1.0000
63.6400 174.0000 1.0000
63.7000 189.0000 1.0000
63.7600 181.0000 1.0000
63.8200 197.0000 1.0000
63.8800 166.0000 1.0000
63.9400 186.0000 1.0000
64.0000 170.0000 1.0000
64.0600 165.0000 1.0000
64.1200 182.0000 1.0000
64.1800 180.0000 1.0000
64.2400 171.0000 1.0000
64.3000 180.0000 1.0000
64.3600 201.0000 1.0000
64.4200 151.0000 1.0000
64.4800 160.0000 1.0000
64.5400 167.0000 1.0000
64.6000 159.0000 1.0000
64.6600 170.0000 1.0000
64.7200 163.0000 1.0000
64.7800 160.0000 1.0000
64.8400 165.0000 1.0000
64.9000 167.0000 1.0000
64.9600 151.0000 1.0000
65.0200 179.0000 1.0000
65.0800 152.0000 1.0000
65.1400 160.0000 1.0000
65.2000 166.0000 1.0000
65.2600 163.0000 1.0000
65.3200 166.0000 1.0000
65.3800 167.0000 1.0000
65.4400 138.0000 1.0000
65.5000 142.0000 1.0000
65.5600 159.0000 1.0000
65.6200 153.0000 1.0000
65.6800 183.0000 1.0000
65.7400 151.0000 1.0000
65.8000 171.0000 1.0000
65.8600 160.0000 1.0000
65.9200 165.0000 1.0000
65.9800 162.0000 1.0000
66.0400 184.0000 1.0000
66.1000 162.0000 1.0000
66.1600 150.0000 1.0000
66.2200 154.0000 1.0000
66.2800 170.0000 1.0000
66.3400 166.0000 1.0000
66.4000 143.0000 1.0000
66.4600 153.0000 1.0000
66.5200 171.0000 1.0000
66.5800 140.0000 1.0000
66.6400 155.0000 1.0000
66.7000 160.0000 1.0000
66.7600 144.0000 1.0000
66.8200 138.0000 1.0000
66.8800 140.0000 1.0000
66.9400 162.0000 1.0000
67.0000 155.0000 1.0000
67.0600 148.0000 1.0000
67.1200 166.0000 1.0000
67.1800 153.0000 1.0000
67.2400 165.0000 1.0000
67.3000 149.0000 1.0000
67.3600 166.0000 1.0000
67.4200 175.0000 1.0000
67.4800 178.0000 1.0000
67.5400 164.0000 1.0000
67.6000 170.0000 1.0000
67.6600 162.0000 1.0000
67.7200 172.0000 1.0000
67.7800 202.0000 1.0000
67.8400 176.0000 1.0000
67.9000 175.0000 1.0000
67.9600 194.0000 1.0000
68.0200 223.0000 1.0000
68.0800 170.0000 1.0000
68.1400 202.0000 1.0000
68.2000 228.0000 1.0000
68.2600 252.0000 1.0000
68.3200 231.0000 1.0000
68.3800 248.0000 1.0000
68.4400 230.0000 1.0000
68.5000 248.0000 1.0000
68.5600 170.0000 1.0000
68.6200 176.0000 1.0000
68.6800 153.0000 1.0000
68.7400 189.0000 1.0000
68.8000 178.0000 1.0000
68.8600 135.0000 1.0000
68.9200 165.0000 1.0000
68.9800 174.0000 1.0000
69.0400 176.0000 1.0000
69.1000 165.0000 1.0000
69.1600 163.0000 1.0000
69.2200 186.0000 1.0000
69.2800 142.0000 1.0000
69.3400 160.0000 1.0000
69.4000 173.0000 1.0000
69.4600 157.0000 1.0000
69.5200 183.0000 1.0000
69.5800 140.0000 1.0000
69.6400 132.0000 1.0000
69.7000 157.0000 1.0000
69.7600 171.0000 1.0000
69.8200 141.0000 1.0000
69.8800 189.0000 1.0000
69.9400 143.0000 1.0000
70.0000 164.0000 1.0000
70.0600 153.0000 1.0000
70.1200 151.0000 1.0000
70.1800 188.0000 1.0000
70.2400 157.0000 1.0000
70.3000 142.0000 1.0000
70.3600 158.0000 1.0000
70.4200 143.0000 1.0000
70.4800 165.0000 1.0000
70.5400 142.0000 1.0000
70.6000 186.0000 1.0000
70.6600 143.0000 1.0000
70.7200 143.0000 1.0000
70.7800 171.0000 1.0000
70.8400 167.0000 1.0000
70.9000 171.0000 1.0000
70.9600 155.0000 1.0000
71.0200 163.0000 1.0000
71.0800 155.0000 1.0000
71.1400 148.0000 1.0000
71.2000 167.0000 1.0000
71.2600 189.0000 1.0000
71.3200 165.0000 1.0000
71.3800 146.0000 1.0000
71.4400 157.0000 1.0000
71.5000 164.0000 1.0000
71.5600 157.0000 1.0000
71.6200 159.0000 1.0000
71.6800 151.0000 1.0000
71.7400 166.0000 1.0000
71.8000 137.0000 1.0000
71.8600 159.0000 1.0000
71.9200 158.0000 1.0000
71.9800 168.0000 1.0000
72.0400 167.0000 1.0000
72.1000 166.0000 1.0000
72.1600 159.0000 1.0000
72.2200 163.0000 1.0000
72.2800 158.0000 1.0000
72.3400 141.0000 1.0000
72.4000 174.0000 1.0000
72.4600 173.0000 1.0000
72.5200 140.0000 1.0000
72.5800 147.0000 1.0000
72.6400 147.0000 1.0000
72.7000 144.0000 1.0000
72.7600 182.0000 1.0000
72.8200 158.0000 1.0000
72.8800 185.0000 1.0000
72.9400 155.0000 1.0000
73.0000 159.0000 1.0000
73.0600 159.0000 1.0000
73.1200 175.0000 1.0000
73.1800 179.0000 1.0000
73.2400 167.0000 1.0000
73.3000 147.0000 1.0000
73.3600 185.0000 1.0000
73.4200 162.0000 1.0000
73.4800 163.0000 1.0000
73.5400 170.0000 1.0000
73.6000 164.0000 1.0000
73.6600 172.0000 1.0000
73.7200 164.0000 1.0000
73.7800 160.0000 1.0000
73.8400 189.0000 1.0000
73.9000 162.0000 1.0000
73.9600 155.0000 1.0000
74.0200 151.0000 1.0000
74.0800 151.0000 1.0000
74.1400 170.0000 1.0000
74.2000 166.0000 1.0000
74.2600 176.0000 1.0000
74.3200 150.0000 1.0000
74.3800 164.0000 1.0000
74.4400 162.0000 1.0000
74.5000 163.0000 1.0000
74.5600 150.0000 1.0000
74.6200 159.0000 1.0000
74.6800 164.0000 1.0000
74.7400 157.0000 1.0000
74.8000 171.0000 1.0000
74.8600 175.0000 1.0000
74.9200 165.0000 1.0000
74.9800 157.0000 1.0000
75.0400 143.0000 1.0000
75.1000 168.0000 1.0000
75.1600 163.0000 1.0000
75.2200 161.0000 1.0000
75.2800 161.0000 1.0000
75.3400 164.0000 1.0000
75.4000 158.0000 1.0000
75.4600 161.0000 1.0000
75.5200 147.0000 1.0000
75.5800 161.0000 1.0000
75.6400 156.0000 1.0000
75.7000 161.0000 1.0000
75.7600 168.0000 1.0000
75.8200 161.0000 1.0000
75.8800 162.0000 1.0000
75.9400 178.0000 1.0000
76.0000 149.0000 1.0000
76.0600 157.0000 1.0000
76.1200 158.0000 1.0000
76.1800 163.0000 1.0000
76.2400 151.0000 1.0000
76.3000 151.0000 1.0000
76.3600 146.0000 1.0000
76.4200 171.0000 1.0000
76.4800 166.0000 1.0000
76.5400 144.0000 1.0000
76.6000 150.0000 1.0000
76.6600 136.0000 1.0000
76.7200 171.0000 1.0000
76.7800 148.0000 1.0000
76.8400 166.0000 1.0000
76.9000 146.0000 1.0000
76.9600 157.0000 1.0000
77.0200 140.0000 1.0000
77.0800 134.0000 1.0000
77.1400 149.0000 1.0000
77.2000 155.0000 1.0000
77.2600 148.0000 1.0000
77.3200 142.0000 1.0000
77.3800 139.0000 1.0000
77.4400 163.0000 1.0000
77.5000 153.0000 1.0000
77.5600 145.0000 1.0000
77.6200 162.0000 1.0000
77.6800 211.0000 1.0000
77.7400 164.0000 1.0000
77.8000 164.0000 1.0000
77.8600 154.0000 1.0000
77.9200 160.0000 1.0000
77.9800 165.0000 1.0000
78.0400 160.0000 1.0000
78.1000 156.0000 1.0000
78.1600 163.0000 1.0000
78.2200 142.0000 1.0000
78.2800 161.0000 1.0000
78.3400 132.0000 1.0000
78.4000 171.0000 1.0000
78.4600 149.0000 1.0000
78.5200 168.0000 1.0000
78.5800 148.0000 1.0000
78.6400 143.0000 1.0000
78.7000 185.0000 1.0000
78.7600 141.0000 1.0000
78.8200 142.0000 1.0000
78.8800 166.0000 1.0000
78.9400 150.0000 1.0000
79.0000 160.0000 1.0000
79.0600 158.0000 1.0000
79.1200 183.0000 1.0000
79.1800 150.0000 1.0000
79.2400 147.0000 1.0000
79.3000 150.0000 1.0000
79.3600 142.0000 1.0000
79.4200 168.0000 1.0000
79.4800 153.0000 1.0000
79.5400 137.0000 1.0000
79.6000 138.0000 1.0000
79.6600 188.0000 1.0000
79.7200 157.0000 1.0000
79.7800 153.0000 1.0000
79.8400 162.0000 1.0000
79.9000 186.0000 1.0000
79.9600 187.0000 1.0000
80.0200 190.0000 1.0000
80.0800 154.0000 1.0000
80.1400 188.0000 1.0000
80.2000 148.0000 1.0000
80.2600 157.0000 1.0000
80.3200 162.0000 1.0000
80.3800 169.0000 1.0000
80.4400 170.0000 1.0000
80.5000 147.0000 1.0000
80.5600 151.0000 1.0000
80.6200 150.0000 1.0000
80.6800 161.0000 1.0000
80.7400 149.0000 1.0000
80.8000 160.0000 1.0000
80.8600 161.0000 1.0000
80.9200 150.0000 1.0000
80.9800 138.0000 1.0000
81.0400 150.0000 1.0000
81.1000 197.0000 1.0000
81.1600 158.0000 1.0000
81.2200 207.0000 1.0000
81.2800 184.0000 1.0000
81.3400 166.0000 1.0000
81.4000 159.0000 1.0000
81.4600 162.0000 1.0000
81.5200 188.0000 1.0000
81.5800 181.0000 1.0000
81.6400 160.0000 1.0000
81.7000 146.0000 1.0000
81.7600 150.0000 1.0000
81.8200 168.0000 1.0000
81.8800 155.0000 1.0000
81.9400 152.0000 1.0000
82.0000 176.0000 1.0000
82.0600 138.0000 1.0000
82.1200 165.0000 1.0000
82.1800 168.0000 1.0000
82.2400 175.0000 1.0000
82.3000 135.0000 1.0000
82.3600 165.0000 1.0000
82.4200 157.0000 1.0000
82.4800 128.0000 1.0000
82.5400 128.0000 1.0000
82.6000 164.0000 1.0000
82.6600 140.0000 1.0000
82.7200 157.0000 1.0000
82.7800 135.0000 1.0000
82.8400 149.0000 1.0000
82.9000 161.0000 1.0000
82.9600 134.0000 1.0000
83.0200 165.0000 1.0000
83.0800 128.0000 1.0000
83.1400 157.0000 1.0000
83.2000 157.0000 1.0000
83.2600 146.0000 1.0000
83.3200 140.0000 1.0000
83.3800 150.0000 1.0000
83.4400 159.0000 1.0000
83.5000 152.0000 1.0000
83.5600 171.0000 1.0000
83.6200 159.0000 1.0000
83.6800 148.0000 1.0000
83.7400 153.0000 1.0000
83.8000 155.0000 1.0000
83.8600 164.0000 1.0000
83.9200 170.0000 1.0000
83.9800 156.0000 1.0000
84.0400 160.0000 1.0000
84.1000 143.0000 1.0000
84.1600 152.0000 1.0000
84.2200 159.0000 1.0000
84.2800 151.0000 1.0000
84.3400 150.0000 1.0000
84.4000 144.0000 1.0000
84.4600 155.0000 1.0000
84.5200 177.0000 1.0000
84.5800 184.0000 1.0000
84.6400 144.0000 1.0000
84.7000 172.0000 1.0000
84.7600 175.0000 1.0000
84.8200 152.0000 1.0000
84.8800 146.0000 1.0000
84.9400 125.0000 1.0000
85.0000 141.0000 1.0000
85.0600 166.0000 1.0000
85.1200 147.0000 1.0000
85.1800 150.0000 1.0000
85.2400 141.0000 1.0000
85.3000 127.0000 1.0000
85.3600 153.0000 1.0000
85.4200 156.0000 1.0000
85.4800 143.0000 1.0000
85.5400 154.0000 1.0000
85.6000 157.0000 1.0000
85.6600 137.0000 1.0000
85.7200 149.0000 1.0000
85.7800 168.0000 1.0000
85.8400 146.0000 1.0000
85.9000 132.0000 1.0000
85.9600 150.0000 1.0000
86.0200 140.0000 1.0000
86.0800 139.0000 1.0000
86.1400 149.0000 1.0000
86.2000 160.0000 1.0000
86.2600 171.0000 1.0000
86.3200 133.0000 1.0000
86.3800 147.0000 1.0000
86.4400 139.0000 1.0000
86.5000 180.0000 1.0000
86.5600 155.0000 1.0000
86.6200 156.0000 1.0000
86.6800 133.0000 1.0000
86.7400 147.0000 1.0000
86.8000 135.0000 1.0000
86.8600 146.0000 1.0000
86.9200 173.0000 1.0000
86.9800 165.0000 1.0000
87.0400 154.0000 1.0000
87.1000 168.0000 1.0000
87.1600 146.0000 1.0000
87.2200 156.0000 1.0000
87.2800 114.0000 1.0000
87.3400 155.0000 1.0000
87.4000 167.0000 1.0000
87.4600 167.0000 1.0000
87.5200 165.0000 1.0000
87.5800 139.0000 1.0000
87.6400 141.0000 1.0000
87.7000 161.0000 1.0000
87.7600 149.0000 1.0000
87.8200 154.0000 1.0000
87.8800 167.0000 1.0000
87.9400 156.0000 1.0000
88.0000 146.0000 1.0000
88.0600 139.0000 1.0000
88.1200 152.0000 1.0000
88.1800 147.0000 1.0000
88.2400 156.0000 1.0000
88.3000 155.0000 1.0000
88.3600 144.0000 1.0000
88.4200 142.0000 1.0000
88.4800 140.0000 1.0000
88.5400 157.0000 1.0000
88.6000 137.0000 1.0000
88.6600 157.0000 1.0000
88.7200 145.0000 1.0000
88.7800 155.0000 1.0000
88.8400 160.0000 1.0000
88.9000 151.0000 1.0000
88.9600 151.0000 1.0000
89.0200 139.0000 1.0000
89.0800 140.0000 1.0000
89.1400 142.0000 1.0000
89.2000 159.0000 1.0000
89.2600 144.0000 1.0000
89.3200 143.0000 1.0000
89.3800 137.0000 1.0000
89.4400 158.0000 1.0000
89.5000 161.0000 1.0000
89.5600 129.0000 1.0000
89.6200 139.0000 1.0000
89.6800 149.0000 1.0000
89.7400 157.0000 1.0000
89.8000 146.0000 1.0000
89.8600 158.0000 1.0000
89.9200 164.0000 1.0000
89.9800 147.0000 1.0000
90.0000 155.0000 1.0000
*RAS_INT_END
*RAS_DATA_END